Workbook

Sheet 使用说明
B2: 工程维修台账 · 使用说明
B3: 一本台账记录全部工单，仪表盘、单元查询自动汇总。日常只需要看第一、三部分。
B5: 一、日常五步
B6: ① 报修登记 | C6: 在【工单台账】最下面一行接着填：报修日期、类型（入户 / 公区）、楼栋、房号或位置、问题描述、维修类别。单据编号、处理天数、该户第几次会自动生成。
B7: ② 派单 | C7: 每天早上在台账顶部给休息的师傅选「休息」。「跟进人1」下拉只列今天上班的师傅；两人协同时再填「跟进人2」。
B8: ③ 上门跟进 | C8: 照常填预约时间、上门排序。没修完之前，「完成情况」保持「跟进中」或「需另约时间」。
B9: ④ 完工 | C9: 「完成情况」改为「已完成」，同时填「完成日期」；有耗材收费的，填「耗材费(元)」。
B10: ⑤ 评价与回访 | C10: 完工后请业主评价，录入「维修评价」「业主意见与建议」。仪表盘第一部分列出未结和重复报修的住户，用来排回访。
B12: 二、各表分工
B13: 工单台账 | C13: 入户和公区的全部工单，用「类型」区分；要单看公区，在表头筛选「类型」即可。顶部是师傅调度看板。
B14: 仪表盘 | C14: 一、现在要处理的事（未结、超期、重复报修）；二、这一期的表现（报修量、完成率、好评率、师傅排行）；三、问题集中在哪（类别、楼栋、师傅×楼栋）。二、三部分按「统计周期」切换当日 / 本周 / 本月 / 累计。
B15: 单元查询 | C15: 选楼栋、填房号，列出这一户的全部维修记录。接业主电话时用。
B16: 设置 | C16: 师傅名单、楼栋、维修类别、统计基准日、超期阈值都在这里改。
B18: 三、哪些格子填，哪些别动
B19: 手工填写 | C19: 台账里黑色表头的列，以及所有米黄色格子（师傅休息、统计周期、查询条件、【设置】里的名单和参数）。
B20: 自动生成 | C20: 台账里灰色表头的三列：单据编号、处理天数、该户第几次；仪表盘、单元查询整张表；【设置】里的灰字计算区。
B21: 新增工单 | C21: 在台账最后一行下面直接填，表格会自动变长，公式、下拉和颜色跟着带下去，不用复制公式。
B23: 四、颜色说明
B24: 陶土橘 | C24: 马上要处理：超期未结、优先 1、跟进人重复。全表最醒目的颜色只留给这几件事。
B25: 浅陶土 | C25: 需要留意：该户第 3 次及以上、需另约时间、不满意、完成日期早于报修日期。
B26: 米黄 | C26: 进行中或待填写：跟进中、未结未超期、该户第 2 次、缺日期 / 类别 / 状态，以及可以改的设置格。
B27: 橄榄绿 | C27: 已完成、满意、非常满意、空闲可派单。
B28: 灰字 | C28: 今天休息的师傅、作废的派单、公式计算区。
B30: 五、配色与排版原则
B31: 可读优先于好看 | C31: 纸色底、墨色字，不用纯白和纯黑；正文文字与底色的对比度都在 4.5:1 以上。
B32: 提醒优先于装饰 | C32: 陶土橘只做底色、不写小字（白字压在陶土橘上看不清），并且只用于必须马上处理的事。
B33: 自动优先于手填 | C33: 能用公式算的就不让人填，例如处理天数、单据编号、该户第几次，减少录入出错。
B34: 宋体说话，等线指路 | C34: 标题和段落标题用宋体，表格、数字、按钮式标签用等线（黑体类），屏幕上小字更清楚。

Sheet 工单台账
A1: 工单台账 ｜ 入户＋公区 | G1: 灰色表头的三列自动生成；在表格最下面一行接着填，公式、下拉和颜色会自动带下去。
A2: 今日调度 | F2: 师傅 | H2: =设置!A9&"" -> 张师傅 | I2: =设置!A10&"" -> 李师傅 | J2: =设置!A11&"" -> 王师傅 | K2: =设置!A12&"" -> 陈师傅 | L2: =设置!A13&"" -> 刘师傅 | M2: ← 名单来自【设置】
A3: ="在岗 "&COUNTIF(H4:L4,"在岗*")&" 人 · 空闲 "&COUNTIF(H4:L4,"空闲")&" 人 · 休息 "&COUNTIF(H4:L4,"休息")&" 人" -> 在岗 4 人 · 空闲 0 人 · 休息 1 人 | F3: 今日休息 | H3: 休息 | I3: 上班 | J3: 上班 | K3: 上班 | L3: 上班 | M3: ← 米黄格每天设一次
A4: 每天早上给休息的师傅选「休息」；名单在【设置】里改。 | F4: 当前状态 | H4: =IF(H2="","",IF(H3="休息","休息",IF(COUNTIFS(工单[跟进人1],H$2,工单[完成情况],"跟进中")+COUNTIFS(工单[跟进人2],H$2,工单[完成情况],"跟进中")>0,"在岗 "&COUNTIFS(工单[跟进人1],H$2,工单[完成情况],"跟进中")+COUNTIFS(工单[跟进人2],H$2,工单[完成情况],"跟进中")&" 单","空闲"))) -> 休息 | I4: =IF(I2="","",IF(I3="休息","休息",IF(COUNTIFS(工单[跟进人1],I$2,工单[完成情况],"跟进中")+COUNTIFS(工单[跟进人2],I$2,工单[完成情况],"跟进中")>0,"在岗 "&COUNTIFS(工单[跟进人1],I$2,工单[完成情况],"跟进中")+COUNTIFS(工单[跟进人2],I$2,工单[完成情况],"跟进中")&" 单","空闲"))) -> 在岗 7 单 | J4: =IF(J2="","",IF(J3="休息","休息",IF(COUNTIFS(工单[跟进人1],J$2,工单[完成情况],"跟进中")+COUNTIFS(工单[跟进人2],J$2,工单[完成情况],"跟进中")>0,"在岗 "&COUNTIFS(工单[跟进人1],J$2,工单[完成情况],"跟进中")+COUNTIFS(工单[跟进人2],J$2,工单[完成情况],"跟进中")&" 单","空闲"))) -> 在岗 1 单 | K4: =IF(K2="","",IF(K3="休息","休息",IF(COUNTIFS(工单[跟进人1],K$2,工单[完成情况],"跟进中")+COUNTIFS(工单[跟进人2],K$2,工单[完成情况],"跟进中")>0,"在岗 "&COUNTIFS(工单[跟进人1],K$2,工单[完成情况],"跟进中")+COUNTIFS(工单[跟进人2],K$2,工单[完成情况],"跟进中")&" 单","空闲"))) -> 在岗 4 单 | L4: =IF(L2="","",IF(L3="休息","休息",IF(COUNTIFS(工单[跟进人1],L$2,工单[完成情况],"跟进中")+COUNTIFS(工单[跟进人2],L$2,工单[完成情况],"跟进中")>0,"在岗 "&COUNTIFS(工单[跟进人1],L$2,工单[完成情况],"跟进中")+COUNTIFS(工单[跟进人2],L$2,工单[完成情况],"跟进中")&" 单","空闲"))) -> 在岗 3 单 | M4: ← 自动：有「跟进中」的单就算在岗
A6: 单据编号 | B6: 报修日期 | C6: 类型 | D6: 楼栋 | E6: 房号/位置 | F6: 报修问题描述 | G6: 维修类别 | H6: 跟进人1 | I6: 跟进人2 | J6: 预约时间 | K6: 上门排序 | L6: 完成情况 | M6: 完成日期 | N6: 处理天数 | O6: 该户第几次 | P6: 维修备注 | Q6: 耗材费(元) | R6: 维修评价 | S6: 业主意见与建议
A7: =IF(OR(工单[[#This Row],[报修日期]]="",工单[[#This Row],[楼栋]]="",工单[[#This Row],[房号/位置]]=""),"待补",IF(工单[[#This Row],[楼栋]]="公共区域","公",IF(工单[[#This Row],[楼栋]]="商铺","S",SUBSTITUTE(工单[[#This Row],[楼栋]],"栋","")))&"-"&工单[[#This Row],[房号/位置]]&"-"&TEXT(MONTH(工单[[#This Row],[报修日期]]),"00")&TEXT(DAY(工单[[#This Row],[报修日期]]),"00")&IF(N(工单[[#This Row],[该户第几次]])>1,"-"&TEXT(工单[[#This Row],[该户第几次]],"00"),"")) -> 8-403-0501 | B7: 45778 | C7: 入户 | D7: 8栋 | E7: 403 | F7: 空调导风百叶断裂更换 | G7: 空调暖通 | H7: 张师傅 | I7: 李师傅 | J7: 5月1日 16:00 | K7: 优先2 | L7: 已完成 | N7: =IF(工单[[#This Row],[报修日期]]="","",IF(工单[[#This Row],[完成情况]]="已完成",IF(工单[[#This Row],[完成日期]]="","",工单[[#This Row],[完成日期]]-工单[[#This Row],[报修日期]]),IF(基准日<工单[[#This Row],[报修日期]],"",基准日-工单[[#This Row],[报修日期]]))) | O7: =IF(OR(工单[[#This Row],[楼栋]]="",工单[[#This Row],[房号/位置]]=""),"",COUNTIFS(INDEX(工单[楼栋],1):工单[[#This Row],[楼栋]],工单[[#This Row],[楼栋]],INDEX(工单[房号/位置],1):工单[[#This Row],[房号/位置]],工单[[#This Row],[房号/位置]])) -> 1 | P7: 业主第3次更改上门时间 | R7: 非常满意
A8: =IF(OR(工单[[#This Row],[报修日期]]="",工单[[#This Row],[楼栋]]="",工单[[#This Row],[房号/位置]]=""),"待补",IF(工单[[#This Row],[楼栋]]="公共区域","公",IF(工单[[#This Row],[楼栋]]="商铺","S",SUBSTITUTE(工单[[#This Row],[楼栋]],"栋","")))&"-"&工单[[#This Row],[房号/位置]]&"-"&TEXT(MONTH(工单[[#This Row],[报修日期]]),"00")&TEXT(DAY(工单[[#This Row],[报修日期]]),"00")&IF(N(工单[[#This Row],[该户第几次]])>1,"-"&TEXT(工单[[#This Row],[该户第几次]],"00"),"")) -> 6-2504-0501 | B8: 45778 | C8: 入户 | D8: 6栋 | E8: 2504 | F8: 空调开机后室内机滴水 | G8: 空调暖通 | H8: 刘师傅 | I8: 张师傅 | J8: 5月1日 10:00 | L8: 跟进中 | N8: =IF(工单[[#This Row],[报修日期]]="","",IF(工单[[#This Row],[完成情况]]="已完成",IF(工单[[#This Row],[完成日期]]="","",工单[[#This Row],[完成日期]]-工单[[#This Row],[报修日期]]),IF(基准日<工单[[#This Row],[报修日期]],"",基准日-工单[[#This Row],[报修日期]]))) -> 6 | O8: =IF(OR(工单[[#This Row],[楼栋]]="",工单[[#This Row],[房号/位置]]=""),"",COUNTIFS(INDEX(工单[楼栋],1):工单[[#This Row],[楼栋]],工单[[#This Row],[楼栋]],INDEX(工单[房号/位置],1):工单[[#This Row],[房号/位置]],工单[[#This Row],[房号/位置]])) -> 1 | P8: 需重新包扎保温棉，待料处理
A9: =IF(OR(工单[[#This Row],[报修日期]]="",工单[[#This Row],[楼栋]]="",工单[[#This Row],[房号/位置]]=""),"待补",IF(工单[[#This Row],[楼栋]]="公共区域","公",IF(工单[[#This Row],[楼栋]]="商铺","S",SUBSTITUTE(工单[[#This Row],[楼栋]],"栋","")))&"-"&工单[[#This Row],[房号/位置]]&"-"&TEXT(MONTH(工单[[#This Row],[报修日期]]),"00")&TEXT(DAY(工单[[#This Row],[报修日期]]),"00")&IF(N(工单[[#This Row],[该户第几次]])>1,"-"&TEXT(工单[[#This Row],[该户第几次]],"00"),"")) -> 5-503-0501 | B9: 45778 | C9: 入户 | D9: 5栋 | E9: 503 | F9: 阳台雨棚接缝漏水 | G9: 渗漏防水 | H9: 刘师傅 | J9: 5月2日 | L9: 已完成 | N9: =IF(工单[[#This Row],[报修日期]]="","",IF(工单[[#This Row],[完成情况]]="已完成",IF(工单[[#This Row],[完成日期]]="","",工单[[#This Row],[完成日期]]-工单[[#This Row],[报修日期]]),IF(基准日<工单[[#This Row],[报修日期]],"",基准日-工单[[#This Row],[报修日期]]))) | O9: =IF(OR(工单[[#This Row],[楼栋]]="",工单[[#This Row],[房号/位置]]=""),"",COUNTIFS(INDEX(工单[楼栋],1):工单[[#This Row],[楼栋]],工单[[#This Row],[楼栋]],INDEX(工单[房号/位置],1):工单[[#This Row],[房号/位置]],工单[[#This Row],[房号/位置]])) -> 1 | P9: 连日下雨，待天晴后另约时间 | R9: 非常满意
A10: =IF(OR(工单[[#This Row],[报修日期]]="",工单[[#This Row],[楼栋]]="",工单[[#This Row],[房号/位置]]=""),"待补",IF(工单[[#This Row],[楼栋]]="公共区域","公",IF(工单[[#This Row],[楼栋]]="商铺","S",SUBSTITUTE(工单[[#This Row],[楼栋]],"栋","")))&"-"&工单[[#This Row],[房号/位置]]&"-"&TEXT(MONTH(工单[[#This Row],[报修日期]]),"00")&TEXT(DAY(工单[[#This Row],[报修日期]]),"00")&IF(N(工单[[#This Row],[该户第几次]])>1,"-"&TEXT(工单[[#This Row],[该户第几次]],"00"),"")) -> 7-2904-0501 | B10: 45778 | C10: 入户 | D10: 7栋 | E10: 2904 | F10: 卧室门把手螺丝滑丝 | G10: 门窗五金 | H10: 张师傅 | J10: 5月1日 上午 | L10: 已完成 | N10: =IF(工单[[#This Row],[报修日期]]="","",IF(工单[[#This Row],[完成情况]]="已完成",IF(工单[[#This Row],[完成日期]]="","",工单[[#This Row],[完成日期]]-工单[[#This Row],[报修日期]]),IF(基准日<工单[[#This Row],[报修日期]],"",基准日-工单[[#This Row],[报修日期]]))) | O10: =IF(OR(工单[[#This Row],[楼栋]]="",工单[[#This Row],[房号/位置]]=""),"",COUNTIFS(INDEX(工单[楼栋],1):工单[[#This Row],[楼栋]],工单[[#This Row],[楼栋]],INDEX(工单[房号/位置],1):工单[[#This Row],[房号/位置]],工单[[#This Row],[房号/位置]])) -> 1 | P10: 物业无同款配件，业主自行采购 | R10: 满意
A11: =IF(OR(工单[[#This Row],[报修日期]]="",工单[[#This Row],[楼栋]]="",工单[[#This Row],[房号/位置]]=""),"待补",IF(工单[[#This Row],[楼栋]]="公共区域","公",IF(工单[[#This Row],[楼栋]]="商铺","S",SUBSTITUTE(工单[[#This Row],[楼栋]],"栋","")))&"-"&工单[[#This Row],[房号/位置]]&"-"&TEXT(MONTH(工单[[#This Row],[报修日期]]),"00")&TEXT(DAY(工单[[#This Row],[报修日期]]),"00")&IF(N(工单[[#This Row],[该户第几次]])>1,"-"&TEXT(工单[[#This Row],[该户第几次]],"00"),"")) -> 6-2004-0501 | B11: 45778 | C11: 入户 | D11: 6栋 | E11: 2004 | F11: 主卧空调出风口结露滴水 | G11: 空调暖通 | H11: 张师傅 | J11: 5月1日 14:00后 | L11: 已完成 | N11: =IF(工单[[#This Row],[报修日期]]="","",IF(工单[[#This Row],[完成情况]]="已完成",IF(工单[[#This Row],[完成日期]]="","",工单[[#This Row],[完成日期]]-工单[[#This Row],[报修日期]]),IF(基准日<工单[[#This Row],[报修日期]],"",基准日-工单[[#This Row],[报修日期]]))) | O11: =IF(OR(工单[[#This Row],[楼栋]]="",工单[[#This Row],[房号/位置]]=""),"",COUNTIFS(INDEX(工单[楼栋],1):工单[[#This Row],[楼栋]],工单[[#This Row],[楼栋]],INDEX(工单[房号/位置],1):工单[[#This Row],[房号/位置]],工单[[#This Row],[房号/位置]])) -> 1 | P11: 已调整出风角度并清洗滤网 | R11: 一般
A12: =IF(OR(工单[[#This Row],[报修日期]]="",工单[[#This Row],[楼栋]]="",工单[[#This Row],[房号/位置]]=""),"待补",IF(工单[[#This Row],[楼栋]]="公共区域","公",IF(工单[[#This Row],[楼栋]]="商铺","S",SUBSTITUTE(工单[[#This Row],[楼栋]],"栋","")))&"-"&工单[[#This Row],[房号/位置]]&"-"&TEXT(MONTH(工单[[#This Row],[报修日期]]),"00")&TEXT(DAY(工单[[#This Row],[报修日期]]),"00")&IF(N(工单[[#This Row],[该户第几次]])>1,"-"&TEXT(工单[[#This Row],[该户第几次]],"00"),"")) -> 6-2501-0501 | B12: 45778 | C12: 入户 | D12: 6栋 | E12: 2501 | F12: 入户门把手松动下垂 | G12: 门窗五金 | H12: 张师傅 | J12: 5月1日 12:00 | L12: 已完成 | N12: =IF(工单[[#This Row],[报修日期]]="","",IF(工单[[#This Row],[完成情况]]="已完成",IF(工单[[#This Row],[完成日期]]="","",工单[[#This Row],[完成日期]]-工单[[#This Row],[报修日期]]),IF(基准日<工单[[#This Row],[报修日期]],"",基准日-工单[[#This Row],[报修日期]]))) | O12: =IF(OR(工单[[#This Row],[楼栋]]="",工单[[#This Row],[房号/位置]]=""),"",COUNTIFS(INDEX(工单[楼栋],1):工单[[#This Row],[楼栋]],工单[[#This Row],[楼栋]],INDEX(工单[房号/位置],1):工单[[#This Row],[房号/位置]],工单[[#This Row],[房号/位置]])) -> 1 | P12: 已紧固复位 | R12: 非常满意 | S12: 师傅来得很快
A13: =IF(OR(工单[[#This Row],[报修日期]]="",工单[[#This Row],[楼栋]]="",工单[[#This Row],[房号/位置]]=""),"待补",IF(工单[[#This Row],[楼栋]]="公共区域","公",IF(工单[[#This Row],[楼栋]]="商铺","S",SUBSTITUTE(工单[[#This Row],[楼栋]],"栋","")))&"-"&工单[[#This Row],[房号/位置]]&"-"&TEXT(MONTH(工单[[#This Row],[报修日期]]),"00")&TEXT(DAY(工单[[#This Row],[报修日期]]),"00")&IF(N(工单[[#This Row],[该户第几次]])>1,"-"&TEXT(工单[[#This Row],[该户第几次]],"00"),"")) -> 6-701-0501 | B13: 45778 | C13: 入户 | D13: 6栋 | E13: 701 | F13: 次卧墙面受潮鼓包起皮 | G13: 墙地饰面 | H13: 李师傅 | J13: 5月1日 14:00后 | K13: 优先1 | L13: 跟进中 | N13: =IF(工单[[#This Row],[报修日期]]="","",IF(工单[[#This Row],[完成情况]]="已完成",IF(工单[[#This Row],[完成日期]]="","",工单[[#This Row],[完成日期]]-工单[[#This Row],[报修日期]]),IF(基准日<工单[[#This Row],[报修日期]],"",基准日-工单[[#This Row],[报修日期]]))) -> 6 | O13: =IF(OR(工单[[#This Row],[楼栋]]="",工单[[#This Row],[房号/位置]]=""),"",COUNTIFS(INDEX(工单[楼栋],1):工单[[#This Row],[楼栋]],工单[[#This Row],[楼栋]],INDEX(工单[房号/位置],1):工单[[#This Row],[房号/位置]],工单[[#This Row],[房号/位置]])) -> 1 | P13: 已铲除鼓包批第一遍腻子，待干透后约第二次上门 | R13: 非常满意 | S13: 可以，辛苦了
A14: =IF(OR(工单[[#This Row],[报修日期]]="",工单[[#This Row],[楼栋]]="",工单[[#This Row],[房号/位置]]=""),"待补",IF(工单[[#This Row],[楼栋]]="公共区域","公",IF(工单[[#This Row],[楼栋]]="商铺","S",SUBSTITUTE(工单[[#This Row],[楼栋]],"栋","")))&"-"&工单[[#This Row],[房号/位置]]&"-"&TEXT(MONTH(工单[[#This Row],[报修日期]]),"00")&TEXT(DAY(工单[[#This Row],[报修日期]]),"00")&IF(N(工单[[#This Row],[该户第几次]])>1,"-"&TEXT(工单[[#This Row],[该户第几次]],"00"),"")) -> 8-1602-0501 | B14: 45778 | C14: 入户 | D14: 8栋 | E14: 1602 | F14: 客厅空调管冷凝水滴落 | G14: 空调暖通 | J14: 5月1日 14:00后 | K14: 优先3 | L14: 跟进中 | N14: =IF(工单[[#This Row],[报修日期]]="","",IF(工单[[#This Row],[完成情况]]="已完成",IF(工单[[#This Row],[完成日期]]="","",工单[[#This Row],[完成日期]]-工单[[#This Row],[报修日期]]),IF(基准日<工单[[#This Row],[报修日期]],"",基准日-工单[[#This Row],[报修日期]]))) -> 6 | O14: =IF(OR(工单[[#This Row],[楼栋]]="",工单[[#This Row],[房号/位置]]=""),"",COUNTIFS(INDEX(工单[楼栋],1):工单[[#This Row],[楼栋]],工单[[#This Row],[楼栋]],INDEX(工单[房号/位置],1):工单[[#This Row],[房号/位置]],工单[[#This Row],[房号/位置]])) -> 1 | P14: 需先由第三方单位为楼上住户空调管加装保温棉
A15: =IF(OR(工单[[#This Row],[报修日期]]="",工单[[#This Row],[楼栋]]="",工单[[#This Row],[房号/位置]]=""),"待补",IF(工单[[#This Row],[楼栋]]="公共区域","公",IF(工单[[#This Row],[楼栋]]="商铺","S",SUBSTITUTE(工单[[#This Row],[楼栋]],"栋","")))&"-"&工单[[#This Row],[房号/位置]]&"-"&TEXT(MONTH(工单[[#This Row],[报修日期]]),"00")&TEXT(DAY(工单[[#This Row],[报修日期]]),"00")&IF(N(工单[[#This Row],[该户第几次]])>1,"-"&TEXT(工单[[#This Row],[该户第几次]],"00"),"")) -> 5-504-0501 | B15: 45778 | C15: 入户 | D15: 5栋 | E15: 504 | F15: 卫生间门把手松动 | G15: 门窗五金 | H15: 张师傅 | J15: 5月1日 17:00前 | L15: 已完成 | N15: =IF(工单[[#This Row],[报修日期]]="","",IF(工单[[#This Row],[完成情况]]="已完成",IF(工单[[#This Row],[完成日期]]="","",工单[[#This Row],[完成日期]]-工单[[#This Row],[报修日期]]),IF(基准日<工单[[#This Row],[报修日期]],"",基准日-工单[[#This Row],[报修日期]]))) | O15: =IF(OR(工单[[#This Row],[楼栋]]="",工单[[#This Row],[房号/位置]]=""),"",COUNTIFS(INDEX(工单[楼栋],1):工单[[#This Row],[楼栋]],工单[[#This Row],[楼栋]],INDEX(工单[房号/位置],1):工单[[#This Row],[房号/位置]],工单[[#This Row],[房号/位置]])) -> 1 | P15: / | R15: 非常满意
A16: =IF(OR(工单[[#This Row],[报修日期]]="",工单[[#This Row],[楼栋]]="",工单[[#This Row],[房号/位置]]=""),"待补",IF(工单[[#This Row],[楼栋]]="公共区域","公",IF(工单[[#This Row],[楼栋]]="商铺","S",SUBSTITUTE(工单[[#This Row],[楼栋]],"栋","")))&"-"&工单[[#This Row],[房号/位置]]&"-"&TEXT(MONTH(工单[[#This Row],[报修日期]]),"00")&TEXT(DAY(工单[[#This Row],[报修日期]]),"00")&IF(N(工单[[#This Row],[该户第几次]])>1,"-"&TEXT(工单[[#This Row],[该户第几次]],"00"),"")) -> 7-304-0501 | B16: 45778 | C16: 入户 | D16: 7栋 | E16: 304 | F16: 阳台天花腻子开裂 | G16: 墙地饰面 | H16: 李师傅 | J16: 5月1日 17:00后 | K16: 优先6 | L16: 已完成 | N16: =IF(工单[[#This Row],[报修日期]]="","",IF(工单[[#This Row],[完成情况]]="已完成",IF(工单[[#This Row],[完成日期]]="","",工单[[#This Row],[完成日期]]-工单[[#This Row],[报修日期]]),IF(基准日<工单[[#This Row],[报修日期]],"",基准日-工单[[#This Row],[报修日期]]))) | O16: =IF(OR(工单[[#This Row],[楼栋]]="",工单[[#This Row],[房号/位置]]=""),"",COUNTIFS(INDEX(工单[楼栋],1):工单[[#This Row],[楼栋]],工单[[#This Row],[楼栋]],INDEX(工单[房号/位置],1):工单[[#This Row],[房号/位置]],工单[[#This Row],[房号/位置]])) -> 1 | R16: 非常满意 | S16: 挺好的，支持物业工作
A17: =IF(OR(工单[[#This Row],[报修日期]]="",工单[[#This Row],[楼栋]]="",工单[[#This Row],[房号/位置]]=""),"待补",IF(工单[[#This Row],[楼栋]]="公共区域","公",IF(工单[[#This Row],[楼栋]]="商铺","S",SUBSTITUTE(工单[[#This Row],[楼栋]],"栋","")))&"-"&工单[[#This Row],[房号/位置]]&"-"&TEXT(MONTH(工单[[#This Row],[报修日期]]),"00")&TEXT(DAY(工单[[#This Row],[报修日期]]),"00")&IF(N(工单[[#This Row],[该户第几次]])>1,"-"&TEXT(工单[[#This Row],[该户第几次]],"00"),"")) -> 10-901-0501 | B17: 45778 | C17: 入户 | D17: 10栋 | E17: 901 | F17: 入户门锁芯转动卡涩 | G17: 门窗五金 | H17: 李师傅 | J17: 5月1日 17:00前 | K17: 优先2 | L17: 已完成 | N17: =IF(工单[[#This Row],[报修日期]]="","",IF(工单[[#This Row],[完成情况]]="已完成",IF(工单[[#This Row],[完成日期]]="","",工单[[#This Row],[完成日期]]-工单[[#This Row],[报修日期]]),IF(基准日<工单[[#This Row],[报修日期]],"",基准日-工单[[#This Row],[报修日期]]))) | O17: =IF(OR(工单[[#This Row],[楼栋]]="",工单[[#This Row],[房号/位置]]=""),"",COUNTIFS(INDEX(工单[楼栋],1):工单[[#This Row],[楼栋]],工单[[#This Row],[楼栋]],INDEX(工单[房号/位置],1):工单[[#This Row],[房号/位置]],工单[[#This Row],[房号/位置]])) -> 1 | P17: / | R17: 非常满意
A18: =IF(OR(工单[[#This Row],[报修日期]]="",工单[[#This Row],[楼栋]]="",工单[[#This Row],[房号/位置]]=""),"待补",IF(工单[[#This Row],[楼栋]]="公共区域","公",IF(工单[[#This Row],[楼栋]]="商铺","S",SUBSTITUTE(工单[[#This Row],[楼栋]],"栋","")))&"-"&工单[[#This Row],[房号/位置]]&"-"&TEXT(MONTH(工单[[#This Row],[报修日期]]),"00")&TEXT(DAY(工单[[#This Row],[报修日期]]),"00")&IF(N(工单[[#This Row],[该户第几次]])>1,"-"&TEXT(工单[[#This Row],[该户第几次]],"00"),"")) -> 9-1204-0501 | B18: 45778 | C18: 入户 | D18: 9栋 | E18: 1204 | F18: 空调出风口面板松脱 | G18: 空调暖通 | H18: 李师傅 | J18: 5月1日 17:00前 | K18: 优先2 | L18: 已完成 | N18: =IF(工单[[#This Row],[报修日期]]="","",IF(工单[[#This Row],[完成情况]]="已完成",IF(工单[[#This Row],[完成日期]]="","",工单[[#This Row],[完成日期]]-工单[[#This Row],[报修日期]]),IF(基准日<工单[[#This Row],[报修日期]],"",基准日-工单[[#This Row],[报修日期]]))) | O18: =IF(OR(工单[[#This Row],[楼栋]]="",工单[[#This Row],[房号/位置]]=""),"",COUNTIFS(INDEX(工单[楼栋],1):工单[[#This Row],[楼栋]],工单[[#This Row],[楼栋]],INDEX(工单[房号/位置],1):工单[[#This Row],[房号/位置]],工单[[#This Row],[房号/位置]])) -> 1 | P18: / | R18: 非常满意 | S18: 师傅动作快，很满意
A19: =IF(OR(工单[[#This Row],[报修日期]]="",工单[[#This Row],[楼栋]]="",工单[[#This Row],[房号/位置]]=""),"待补",IF(工单[[#This Row],[楼栋]]="公共区域","公",IF(工单[[#This Row],[楼栋]]="商铺","S",SUBSTITUTE(工单[[#This Row],[楼栋]],"栋","")))&"-"&工单[[#This Row],[房号/位置]]&"-"&TEXT(MONTH(工单[[#This Row],[报修日期]]),"00")&TEXT(DAY(工单[[#This Row],[报修日期]]),"00")&IF(N(工单[[#This Row],[该户第几次]])>1,"-"&TEXT(工单[[#This Row],[该户第几次]],"00"),"")) -> 1-1203-0501 | B19: 45778 | C19: 入户 | D19: 1栋 | E19: 1203 | F19: 智能门锁电量低打不开 | G19: 门窗五金 | H19: 刘师傅 | J19: 5月1日 16:51 | K19: 优先1 | L19: 已完成 | N19: =IF(工单[[#This Row],[报修日期]]="","",IF(工单[[#This Row],[完成情况]]="已完成",IF(工单[[#This Row],[完成日期]]="","",工单[[#This Row],[完成日期]]-工单[[#This Row],[报修日期]]),IF(基准日<工单[[#This Row],[报修日期]],"",基准日-工单[[#This Row],[报修日期]]))) | O19: =IF(OR(工单[[#This Row],[楼栋]]="",工单[[#This Row],[房号/位置]]=""),"",COUNTIFS(INDEX(工单[楼栋],1):工单[[#This Row],[楼栋]],工单[[#This Row],[楼栋]],INDEX(工单[房号/位置],1):工单[[#This Row],[房号/位置]],工单[[#This Row],[房号/位置]])) -> 1 | P19: / | R19: 非常满意
A20: =IF(OR(工单[[#This Row],[报修日期]]="",工单[[#This Row],[楼栋]]="",工单[[#This Row],[房号/位置]]=""),"待补",IF(工单[[#This Row],[楼栋]]="公共区域","公",IF(工单[[#This Row],[楼栋]]="商铺","S",SUBSTITUTE(工单[[#This Row],[楼栋]],"栋","")))&"-"&工单[[#This Row],[房号/位置]]&"-"&TEXT(MONTH(工单[[#This Row],[报修日期]]),"00")&TEXT(DAY(工单[[#This Row],[报修日期]]),"00")&IF(N(工单[[#This Row],[该户第几次]])>1,"-"&TEXT(工单[[#This Row],[该户第几次]],"00"),"")) -> 8-3101-0501 | B20: 45778 | C20: 入户 | D20: 8栋 | E20: 3101 | F20: 咨询车位充电桩怎么走线 | G20: 电气照明 | H20: 李师傅 | J20: 5月1日 20:30 | L20: 已完成 | N20: =IF(工单[[#This Row],[报修日期]]="","",IF(工单[[#This Row],[完成情况]]="已完成",IF(工单[[#This Row],[完成日期]]="","",工单[[#This Row],[完成日期]]-工单[[#This Row],[报修日期]]),IF(基准日<工单[[#This Row],[报修日期]],"",基准日-工单[[#This Row],[报修日期]]))) | O20: =IF(OR(工单[[#This Row],[楼栋]]="",工单[[#This Row],[房号/位置]]=""),"",COUNTIFS(INDEX(工单[楼栋],1):工单[[#This Row],[楼栋]],工单[[#This Row],[楼栋]],INDEX(工单[房号/位置],1):工单[[#This Row],[房号/位置]],工单[[#This Row],[房号/位置]])) -> 1 | R20: 非常满意
A21: =IF(OR(工单[[#This Row],[报修日期]]="",工单[[#This Row],[楼栋]]="",工单[[#This Row],[房号/位置]]=""),"待补",IF(工单[[#This Row],[楼栋]]="公共区域","公",IF(工单[[#This Row],[楼栋]]="商铺","S",SUBSTITUTE(工单[[#This Row],[楼栋]],"栋","")))&"-"&工单[[#This Row],[房号/位置]]&"-"&TEXT(MONTH(工单[[#This Row],[报修日期]]),"00")&TEXT(DAY(工单[[#This Row],[报修日期]]),"00")&IF(N(工单[[#This Row],[该户第几次]])>1,"-"&TEXT(工单[[#This Row],[该户第几次]],"00"),"")) -> 8-1501-0501 | B21: 45778 | C21: 入户 | D21: 8栋 | E21: 1501 | F21: 客厅地板有水珠，疑似空调滴水 | G21: 空调暖通 | H21: 李师傅 | J21: 5月1日 16:00 | L21: 已完成 | N21: =IF(工单[[#This Row],[报修日期]]="","",IF(工单[[#This Row],[完成情况]]="已完成",IF(工单[[#This Row],[完成日期]]="","",工单[[#This Row],[完成日期]]-工单[[#This Row],[报修日期]]),IF(基准日<工单[[#This Row],[报修日期]],"",基准日-工单[[#This Row],[报修日期]]))) | O21: =IF(OR(工单[[#This Row],[楼栋]]="",工单[[#This Row],[房号/位置]]=""),"",COUNTIFS(INDEX(工单[楼栋],1):工单[[#This Row],[楼栋]],工单[[#This Row],[楼栋]],INDEX(工单[房号/位置],1):工单[[#This Row],[房号/位置]],工单[[#This Row],[房号/位置]])) -> 1 | P21: 已更换空调出风口并加贴保温棉 | R21: 满意
A22: =IF(OR(工单[[#This Row],[报修日期]]="",工单[[#This Row],[楼栋]]="",工单[[#This Row],[房号/位置]]=""),"待补",IF(工单[[#This Row],[楼栋]]="公共区域","公",IF(工单[[#This Row],[楼栋]]="商铺","S",SUBSTITUTE(工单[[#This Row],[楼栋]],"栋","")))&"-"&工单[[#This Row],[房号/位置]]&"-"&TEXT(MONTH(工单[[#This Row],[报修日期]]),"00")&TEXT(DAY(工单[[#This Row],[报修日期]]),"00")&IF(N(工单[[#This Row],[该户第几次]])>1,"-"&TEXT(工单[[#This Row],[该户第几次]],"00"),"")) -> 11-1402-0501 | B22: 45778 | C22: 入户 | D22: 11栋 | E22: 1402 | F22: 主卧门锁卡死、入户门关闭变紧 | G22: 门窗五金 | H22: 李师傅 | J22: 5月1日 19:00 | K22: 优先1 | L22: 已完成 | N22: =IF(工单[[#This Row],[报修日期]]="","",IF(工单[[#This Row],[完成情况]]="已完成",IF(工单[[#This Row],[完成日期]]="","",工单[[#This Row],[完成日期]]-工单[[#This Row],[报修日期]]),IF(基准日<工单[[#This Row],[报修日期]],"",基准日-工单[[#This Row],[报修日期]]))) | O22: =IF(OR(工单[[#This Row],[楼栋]]="",工单[[#This Row],[房号/位置]]=""),"",COUNTIFS(INDEX(工单[楼栋],1):工单[[#This Row],[楼栋]],工单[[#This Row],[楼栋]],INDEX(工单[房号/位置],1):工单[[#This Row],[房号/位置]],工单[[#This Row],[房号/位置]])) -> 1 | P22: 另约5月2号上门 | R22: 非常满意
A23: =IF(OR(工单[[#This Row],[报修日期]]="",工单[[#This Row],[楼栋]]="",工单[[#This Row],[房号/位置]]=""),"待补",IF(工单[[#This Row],[楼栋]]="公共区域","公",IF(工单[[#This Row],[楼栋]]="商铺","S",SUBSTITUTE(工单[[#This Row],[楼栋]],"栋","")))&"-"&工单[[#This Row],[房号/位置]]&"-"&TEXT(MONTH(工单[[#This Row],[报修日期]]),"00")&TEXT(DAY(工单[[#This Row],[报修日期]]),"00")&IF(N(工单[[#This Row],[该户第几次]])>1,"-"&TEXT(工单[[#This Row],[该户第几次]],"00"),"")) -> 5-2803-0501 | B23: 45778 | C23: 入户 | D23: 5栋 | E23: 2803 | F23: 厨房洗菜盆下水堵塞 | G23: 给排水 | H23: 李师傅 | J23: 5月1日 21:30 | L23: 已完成 | N23: =IF(工单[[#This Row],[报修日期]]="","",IF(工单[[#This Row],[完成情况]]="已完成",IF(工单[[#This Row],[完成日期]]="","",工单[[#This Row],[完成日期]]-工单[[#This Row],[报修日期]]),IF(基准日<工单[[#This Row],[报修日期]],"",基准日-工单[[#This Row],[报修日期]]))) | O23: =IF(OR(工单[[#This Row],[楼栋]]="",工单[[#This Row],[房号/位置]]=""),"",COUNTIFS(INDEX(工单[楼栋],1):工单[[#This Row],[楼栋]],工单[[#This Row],[楼栋]],INDEX(工单[房号/位置],1):工单[[#This Row],[房号/位置]],工单[[#This Row],[房号/位置]])) -> 1 | R23: 非常满意 | S23: 业主来电点赞表扬
A24: =IF(OR(工单[[#This Row],[报修日期]]="",工单[[#This Row],[楼栋]]="",工单[[#This Row],[房号/位置]]=""),"待补",IF(工单[[#This Row],[楼栋]]="公共区域","公",IF(工单[[#This Row],[楼栋]]="商铺","S",SUBSTITUTE(工单[[#This Row],[楼栋]],"栋","")))&"-"&工单[[#This Row],[房号/位置]]&"-"&TEXT(MONTH(工单[[#This Row],[报修日期]]),"00")&TEXT(DAY(工单[[#This Row],[报修日期]]),"00")&IF(N(工单[[#This Row],[该户第几次]])>1,"-"&TEXT(工单[[#This Row],[该户第几次]],"00"),"")) -> 10-1103-0501 | B24: 45778 | C24: 入户 | D24: 10栋 | E24: 1103 | F24: 多个门把手松动、淋浴房门下沉 | G24: 门窗五金 | H24: 李师傅 | J24: 5月1日 21:50 | L24: 已完成 | N24: =IF(工单[[#This Row],[报修日期]]="","",IF(工单[[#This Row],[完成情况]]="已完成",IF(工单[[#This Row],[完成日期]]="","",工单[[#This Row],[完成日期]]-工单[[#This Row],[报修日期]]),IF(基准日<工单[[#This Row],[报修日期]],"",基准日-工单[[#This Row],[报修日期]]))) | O24: =IF(OR(工单[[#This Row],[楼栋]]="",工单[[#This Row],[房号/位置]]=""),"",COUNTIFS(INDEX(工单[楼栋],1):工单[[#This Row],[楼栋]],工单[[#This Row],[楼栋]],INDEX(工单[房号/位置],1):工单[[#This Row],[房号/位置]],工单[[#This Row],[房号/位置]])) -> 1 | R24: 非常满意
A25: =IF(OR(工单[[#This Row],[报修日期]]="",工单[[#This Row],[楼栋]]="",工单[[#This Row],[房号/位置]]=""),"待补",IF(工单[[#This Row],[楼栋]]="公共区域","公",IF(工单[[#This Row],[楼栋]]="商铺","S",SUBSTITUTE(工单[[#This Row],[楼栋]],"栋","")))&"-"&工单[[#This Row],[房号/位置]]&"-"&TEXT(MONTH(工单[[#This Row],[报修日期]]),"00")&TEXT(DAY(工单[[#This Row],[报修日期]]),"00")&IF(N(工单[[#This Row],[该户第几次]])>1,"-"&TEXT(工单[[#This Row],[该户第几次]],"00"),"")) -> 3-2901-0501 | B25: 45778 | C25: 入户 | D25: 3栋 | E25: 2901 | F25: 主卧空调久未使用，开机有异味 | G25: 空调暖通 | H25: 张师傅 | J25: 5月1日 上午 | L25: 已完成 | N25: =IF(工单[[#This Row],[报修日期]]="","",IF(工单[[#This Row],[完成情况]]="已完成",IF(工单[[#This Row],[完成日期]]="","",工单[[#This Row],[完成日期]]-工单[[#This Row],[报修日期]]),IF(基准日<工单[[#This Row],[报修日期]],"",基准日-工单[[#This Row],[报修日期]]))) | O25: =IF(OR(工单[[#This Row],[楼栋]]="",工单[[#This Row],[房号/位置]]=""),"",COUNTIFS(INDEX(工单[楼栋],1):工单[[#This Row],[楼栋]],工单[[#This Row],[楼栋]],INDEX(工单[房号/位置],1):工单[[#This Row],[房号/位置]],工单[[#This Row],[房号/位置]])) -> 1 | R25: 非常满意
A26: =IF(OR(工单[[#This Row],[报修日期]]="",工单[[#This Row],[楼栋]]="",工单[[#This Row],[房号/位置]]=""),"待补",IF(工单[[#This Row],[楼栋]]="公共区域","公",IF(工单[[#This Row],[楼栋]]="商铺","S",SUBSTITUTE(工单[[#This Row],[楼栋]],"栋","")))&"-"&工单[[#This Row],[房号/位置]]&"-"&TEXT(MONTH(工单[[#This Row],[报修日期]]),"00")&TEXT(DAY(工单[[#This Row],[报修日期]]),"00")&IF(N(工单[[#This Row],[该户第几次]])>1,"-"&TEXT(工单[[#This Row],[该户第几次]],"00"),"")) -> 2-2604-0501 | B26: 45778 | C26: 入户 | D26: 2栋 | E26: 2604 | F26: 卫生间门吸脱落 | G26: 门窗五金 | H26: 李师傅 | J26: 5月1日 15:00 | K26: 优先2 | L26: 已完成 | N26: =IF(工单[[#This Row],[报修日期]]="","",IF(工单[[#This Row],[完成情况]]="已完成",IF(工单[[#This Row],[完成日期]]="","",工单[[#This Row],[完成日期]]-工单[[#This Row],[报修日期]]),IF(基准日<工单[[#This Row],[报修日期]],"",基准日-工单[[#This Row],[报修日期]]))) | O26: =IF(OR(工单[[#This Row],[楼栋]]="",工单[[#This Row],[房号/位置]]=""),"",COUNTIFS(INDEX(工单[楼栋],1):工单[[#This Row],[楼栋]],工单[[#This Row],[楼栋]],INDEX(工单[房号/位置],1):工单[[#This Row],[房号/位置]],工单[[#This Row],[房号/位置]])) -> 1 | R26: 非常满意
A27: =IF(OR(工单[[#This Row],[报修日期]]="",工单[[#This Row],[楼栋]]="",工单[[#This Row],[房号/位置]]=""),"待补",IF(工单[[#This Row],[楼栋]]="公共区域","公",IF(工单[[#This Row],[楼栋]]="商铺","S",SUBSTITUTE(工单[[#This Row],[楼栋]],"栋","")))&"-"&工单[[#This Row],[房号/位置]]&"-"&TEXT(MONTH(工单[[#This Row],[报修日期]]),"00")&TEXT(DAY(工单[[#This Row],[报修日期]]),"00")&IF(N(工单[[#This Row],[该户第几次]])>1,"-"&TEXT(工单[[#This Row],[该户第几次]],"00"),"")) -> 4-3104-0501 | B27: 45778 | C27: 入户 | D27: 4栋 | E27: 3104 | F27: 厨房水龙头出水忽大忽小 | G27: 给排水 | H27: 刘师傅 | J27: 5月1日 下午 | L27: 已完成 | N27: =IF(工单[[#This Row],[报修日期]]="","",IF(工单[[#This Row],[完成情况]]="已完成",IF(工单[[#This Row],[完成日期]]="","",工单[[#This Row],[完成日期]]-工单[[#This Row],[报修日期]]),IF(基准日<工单[[#This Row],[报修日期]],"",基准日-工单[[#This Row],[报修日期]]))) | O27: =IF(OR(工单[[#This Row],[楼栋]]="",工单[[#This Row],[房号/位置]]=""),"",COUNTIFS(INDEX(工单[楼栋],1):工单[[#This Row],[楼栋]],工单[[#This Row],[楼栋]],INDEX(工单[房号/位置],1):工单[[#This Row],[房号/位置]],工单[[#This Row],[房号/位置]])) -> 1 | P27: 已拆洗起泡器滤网 | R27: 满意
A28: =IF(OR(工单[[#This Row],[报修日期]]="",工单[[#This Row],[楼栋]]="",工单[[#This Row],[房号/位置]]=""),"待补",IF(工单[[#This Row],[楼栋]]="公共区域","公",IF(工单[[#This Row],[楼栋]]="商铺","S",SUBSTITUTE(工单[[#This Row],[楼栋]],"栋","")))&"-"&工单[[#This Row],[房号/位置]]&"-"&TEXT(MONTH(工单[[#This Row],[报修日期]]),"00")&TEXT(DAY(工单[[#This Row],[报修日期]]),"00")&IF(N(工单[[#This Row],[该户第几次]])>1,"-"&TEXT(工单[[#This Row],[该户第几次]],"00"),"")) -> 9-501-0501 | B28: 45778 | C28: 入户 | D28: 9栋 | E28: 501 | F28: 客厅踢脚线脱胶翘起 | G28: 墙地饰面 | H28: 张师傅 | J28: 5月1日 18:00 | L28: 已完成 | N28: =IF(工单[[#This Row],[报修日期]]="","",IF(工单[[#This Row],[完成情况]]="已完成",IF(工单[[#This Row],[完成日期]]="","",工单[[#This Row],[完成日期]]-工单[[#This Row],[报修日期]]),IF(基准日<工单[[#This Row],[报修日期]],"",基准日-工单[[#This Row],[报修日期]]))) | O28: =IF(OR(工单[[#This Row],[楼栋]]="",工单[[#This Row],[房号/位置]]=""),"",COUNTIFS(INDEX(工单[楼栋],1):工单[[#This Row],[楼栋]],工单[[#This Row],[楼栋]],INDEX(工单[房号/位置],1):工单[[#This Row],[房号/位置]],工单[[#This Row],[房号/位置]])) -> 1 | R28: 非常满意 | S28: 师傅很细心，处理得很干净
A29: =IF(OR(工单[[#This Row],[报修日期]]="",工单[[#This Row],[楼栋]]="",工单[[#This Row],[房号/位置]]=""),"待补",IF(工单[[#This Row],[楼栋]]="公共区域","公",IF(工单[[#This Row],[楼栋]]="商铺","S",SUBSTITUTE(工单[[#This Row],[楼栋]],"栋","")))&"-"&工单[[#This Row],[房号/位置]]&"-"&TEXT(MONTH(工单[[#This Row],[报修日期]]),"00")&TEXT(DAY(工单[[#This Row],[报修日期]]),"00")&IF(N(工单[[#This Row],[该户第几次]])>1,"-"&TEXT(工单[[#This Row],[该户第几次]],"00"),"")) -> 11-802-0501 | B29: 45778 | C29: 入户 | D29: 11栋 | E29: 802 | F29: 阳台推拉门推拉费劲 | G29: 门窗五金 | H29: 李师傅 | J29: 5月1日 19:30 | K29: 优先3 | L29: 已完成 | N29: =IF(工单[[#This Row],[报修日期]]="","",IF(工单[[#This Row],[完成情况]]="已完成",IF(工单[[#This Row],[完成日期]]="","",工单[[#This Row],[完成日期]]-工单[[#This Row],[报修日期]]),IF(基准日<工单[[#This Row],[报修日期]],"",基准日-工单[[#This Row],[报修日期]]))) | O29: =IF(OR(工单[[#This Row],[楼栋]]="",工单[[#This Row],[房号/位置]]=""),"",COUNTIFS(INDEX(工单[楼栋],1):工单[[#This Row],[楼栋]],工单[[#This Row],[楼栋]],INDEX(工单[房号/位置],1):工单[[#This Row],[房号/位置]],工单[[#This Row],[房号/位置]])) -> 1 | R29: 非常满意
A30: =IF(OR(工单[[#This Row],[报修日期]]="",工单[[#This Row],[楼栋]]="",工单[[#This Row],[房号/位置]]=""),"待补",IF(工单[[#This Row],[楼栋]]="公共区域","公",IF(工单[[#This Row],[楼栋]]="商铺","S",SUBSTITUTE(工单[[#This Row],[楼栋]],"栋","")))&"-"&工单[[#This Row],[房号/位置]]&"-"&TEXT(MONTH(工单[[#This Row],[报修日期]]),"00")&TEXT(DAY(工单[[#This Row],[报修日期]]),"00")&IF(N(工单[[#This Row],[该户第几次]])>1,"-"&TEXT(工单[[#This Row],[该户第几次]],"00"),"")) -> 6-2701-0501 | B30: 45778 | C30: 入户 | D30: 6栋 | E30: 2701 | F30: 次卧顶灯开关按了没反应 | G30: 电气照明 | H30: 张师傅 | J30: 5月1日 20:00 | L30: 已完成 | N30: =IF(工单[[#This Row],[报修日期]]="","",IF(工单[[#This Row],[完成情况]]="已完成",IF(工单[[#This Row],[完成日期]]="","",工单[[#This Row],[完成日期]]-工单[[#This Row],[报修日期]]),IF(基准日<工单[[#This Row],[报修日期]],"",基准日-工单[[#This Row],[报修日期]]))) | O30: =IF(OR(工单[[#This Row],[楼栋]]="",工单[[#This Row],[房号/位置]]=""),"",COUNTIFS(INDEX(工单[楼栋],1):工单[[#This Row],[楼栋]],工单[[#This Row],[楼栋]],INDEX(工单[房号/位置],1):工单[[#This Row],[房号/位置]],工单[[#This Row],[房号/位置]])) -> 1 | P30: 已更换开关面板 | R30: 非常满意
A31: =IF(OR(工单[[#This Row],[报修日期]]="",工单[[#This Row],[楼栋]]="",工单[[#This Row],[房号/位置]]=""),"待补",IF(工单[[#This Row],[楼栋]]="公共区域","公",IF(工单[[#This Row],[楼栋]]="商铺","S",SUBSTITUTE(工单[[#This Row],[楼栋]],"栋","")))&"-"&工单[[#This Row],[房号/位置]]&"-"&TEXT(MONTH(工单[[#This Row],[报修日期]]),"00")&TEXT(DAY(工单[[#This Row],[报修日期]]),"00")&IF(N(工单[[#This Row],[该户第几次]])>1,"-"&TEXT(工单[[#This Row],[该户第几次]],"00"),"")) -> 9-乒乓球位置-0501 | B31: 45778 | C31: 公区 | D31: 9栋 | E31: 乒乓球位置 | F31: 五一活动临时送电 | G31: 电气照明 | H31: 张师傅 | J31: 5月1日 上午 | L31: 已完成 | N31: =IF(工单[[#This Row],[报修日期]]="","",IF(工单[[#This Row],[完成情况]]="已完成",IF(工单[[#This Row],[完成日期]]="","",工单[[#This Row],[完成日期]]-工单[[#This Row],[报修日期]]),IF(基准日<工单[[#This Row],[报修日期]],"",基准日-工单[[#This Row],[报修日期]]))) | O31: =IF(OR(工单[[#This Row],[楼栋]]="",工单[[#This Row],[房号/位置]]=""),"",COUNTIFS(INDEX(工单[楼栋],1):工单[[#This Row],[楼栋]],工单[[#This Row],[楼栋]],INDEX(工单[房号/位置],1):工单[[#This Row],[房号/位置]],工单[[#This Row],[房号/位置]])) -> 1
A32: =IF(OR(工单[[#This Row],[报修日期]]="",工单[[#This Row],[楼栋]]="",工单[[#This Row],[房号/位置]]=""),"待补",IF(工单[[#This Row],[楼栋]]="公共区域","公",IF(工单[[#This Row],[楼栋]]="商铺","S",SUBSTITUTE(工单[[#This Row],[楼栋]],"栋","")))&"-"&工单[[#This Row],[房号/位置]]&"-"&TEXT(MONTH(工单[[#This Row],[报修日期]]),"00")&TEXT(DAY(工单[[#This Row],[报修日期]]),"00")&IF(N(工单[[#This Row],[该户第几次]])>1,"-"&TEXT(工单[[#This Row],[该户第几次]],"00"),"")) -> 公-东大门-0501 | B32: 45778 | C32: 公区 | D32: 公共区域 | E32: 东大门 | F32: 门岗二楼遮阳帘松脱需加固 | G32: 公共设施 | H32: 陈师傅 | I32: 王师傅 | J32: 5月1日 上午 | L32: 已完成 | N32: =IF(工单[[#This Row],[报修日期]]="","",IF(工单[[#This Row],[完成情况]]="已完成",IF(工单[[#This Row],[完成日期]]="","",工单[[#This Row],[完成日期]]-工单[[#This Row],[报修日期]]),IF(基准日<工单[[#This Row],[报修日期]],"",基准日-工单[[#This Row],[报修日期]]))) | O32: =IF(OR(工单[[#This Row],[楼栋]]="",工单[[#This Row],[房号/位置]]=""),"",COUNTIFS(INDEX(工单[楼栋],1):工单[[#This Row],[楼栋]],工单[[#This Row],[楼栋]],INDEX(工单[房号/位置],1):工单[[#This Row],[房号/位置]],工单[[#This Row],[房号/位置]])) -> 1
A33: =IF(OR(工单[[#This Row],[报修日期]]="",工单[[#This Row],[楼栋]]="",工单[[#This Row],[房号/位置]]=""),"待补",IF(工单[[#This Row],[楼栋]]="公共区域","公",IF(工单[[#This Row],[楼栋]]="商铺","S",SUBSTITUTE(工单[[#This Row],[楼栋]],"栋","")))&"-"&工单[[#This Row],[房号/位置]]&"-"&TEXT(MONTH(工单[[#This Row],[报修日期]]),"00")&TEXT(DAY(工单[[#This Row],[报修日期]]),"00")&IF(N(工单[[#This Row],[该户第几次]])>1,"-"&TEXT(工单[[#This Row],[该户第几次]],"00"),"")) -> 公-西门车库出口-0501 | B33: 45778 | C33: 公区 | D33: 公共区域 | E33: 西门车库出口 | F33: 出口道闸识别车牌后不抬杆 | G33: 弱电门禁 | H33: 陈师傅 | I33: 王师傅 | J33: 5月1日 上午 | L33: 已完成 | N33: =IF(工单[[#This Row],[报修日期]]="","",IF(工单[[#This Row],[完成情况]]="已完成",IF(工单[[#This Row],[完成日期]]="","",工单[[#This Row],[完成日期]]-工单[[#This Row],[报修日期]]),IF(基准日<工单[[#This Row],[报修日期]],"",基准日-工单[[#This Row],[报修日期]]))) | O33: =IF(OR(工单[[#This Row],[楼栋]]="",工单[[#This Row],[房号/位置]]=""),"",COUNTIFS(INDEX(工单[楼栋],1):工单[[#This Row],[楼栋]],工单[[#This Row],[楼栋]],INDEX(工单[房号/位置],1):工单[[#This Row],[房号/位置]],工单[[#This Row],[房号/位置]])) -> 1
A34: =IF(OR(工单[[#This Row],[报修日期]]="",工单[[#This Row],[楼栋]]="",工单[[#This Row],[房号/位置]]=""),"待补",IF(工单[[#This Row],[楼栋]]="公共区域","公",IF(工单[[#This Row],[楼栋]]="商铺","S",SUBSTITUTE(工单[[#This Row],[楼栋]],"栋","")))&"-"&工单[[#This Row],[房号/位置]]&"-"&TEXT(MONTH(工单[[#This Row],[报修日期]]),"00")&TEXT(DAY(工单[[#This Row],[报修日期]]),"00")&IF(N(工单[[#This Row],[该户第几次]])>1,"-"&TEXT(工单[[#This Row],[该户第几次]],"00"),"")) -> 3-货梯-0501 | B34: 45778 | C34: 公区 | D34: 3栋 | E34: 货梯 | F34: 货梯轿厢空调不制冷 | G34: 空调暖通 | H34: 陈师傅 | J34: 5月1日 下午 | L34: 已完成 | N34: =IF(工单[[#This Row],[报修日期]]="","",IF(工单[[#This Row],[完成情况]]="已完成",IF(工单[[#This Row],[完成日期]]="","",工单[[#This Row],[完成日期]]-工单[[#This Row],[报修日期]]),IF(基准日<工单[[#This Row],[报修日期]],"",基准日-工单[[#This Row],[报修日期]]))) | O34: =IF(OR(工单[[#This Row],[楼栋]]="",工单[[#This Row],[房号/位置]]=""),"",COUNTIFS(INDEX(工单[楼栋],1):工单[[#This Row],[楼栋]],工单[[#This Row],[楼栋]],INDEX(工单[房号/位置],1):工单[[#This Row],[房号/位置]],工单[[#This Row],[房号/位置]])) -> 1
A35: =IF(OR(工单[[#This Row],[报修日期]]="",工单[[#This Row],[楼栋]]="",工单[[#This Row],[房号/位置]]=""),"待补",IF(工单[[#This Row],[楼栋]]="公共区域","公",IF(工单[[#This Row],[楼栋]]="商铺","S",SUBSTITUTE(工单[[#This Row],[楼栋]],"栋","")))&"-"&工单[[#This Row],[房号/位置]]&"-"&TEXT(MONTH(工单[[#This Row],[报修日期]]),"00")&TEXT(DAY(工单[[#This Row],[报修日期]]),"00")&IF(N(工单[[#This Row],[该户第几次]])>1,"-"&TEXT(工单[[#This Row],[该户第几次]],"00"),"")) -> 9-肉菜市场-0501 | B35: 45778 | C35: 公区 | D35: 9栋 | E35: 肉菜市场 | F35: 市场内墙雨后渗水 | G35: 渗漏防水 | H35: 刘师傅 | L35: 跟进中 | N35: =IF(工单[[#This Row],[报修日期]]="","",IF(工单[[#This Row],[完成情况]]="已完成",IF(工单[[#This Row],[完成日期]]="","",工单[[#This Row],[完成日期]]-工单[[#This Row],[报修日期]]),IF(基准日<工单[[#This Row],[报修日期]],"",基准日-工单[[#This Row],[报修日期]]))) -> 6 | O35: =IF(OR(工单[[#This Row],[楼栋]]="",工单[[#This Row],[房号/位置]]=""),"",COUNTIFS(INDEX(工单[楼栋],1):工单[[#This Row],[楼栋]],工单[[#This Row],[楼栋]],INDEX(工单[房号/位置],1):工单[[#This Row],[房号/位置]],工单[[#This Row],[房号/位置]])) -> 1 | P35: 待跟进
A36: =IF(OR(工单[[#This Row],[报修日期]]="",工单[[#This Row],[楼栋]]="",工单[[#This Row],[房号/位置]]=""),"待补",IF(工单[[#This Row],[楼栋]]="公共区域","公",IF(工单[[#This Row],[楼栋]]="商铺","S",SUBSTITUTE(工单[[#This Row],[楼栋]],"栋","")))&"-"&工单[[#This Row],[房号/位置]]&"-"&TEXT(MONTH(工单[[#This Row],[报修日期]]),"00")&TEXT(DAY(工单[[#This Row],[报修日期]]),"00")&IF(N(工单[[#This Row],[该户第几次]])>1,"-"&TEXT(工单[[#This Row],[该户第几次]],"00"),"")) -> 10-1层-0501 | B36: 45778 | C36: 公区 | D36: 10栋 | E36: 1层 | F36: 单元大门下沉刮地 | G36: 门窗五金 | H36: 陈师傅 | J36: 5月1日 14:00后 | L36: 已完成 | N36: =IF(工单[[#This Row],[报修日期]]="","",IF(工单[[#This Row],[完成情况]]="已完成",IF(工单[[#This Row],[完成日期]]="","",工单[[#This Row],[完成日期]]-工单[[#This Row],[报修日期]]),IF(基准日<工单[[#This Row],[报修日期]],"",基准日-工单[[#This Row],[报修日期]]))) | O36: =IF(OR(工单[[#This Row],[楼栋]]="",工单[[#This Row],[房号/位置]]=""),"",COUNTIFS(INDEX(工单[楼栋],1):工单[[#This Row],[楼栋]],工单[[#This Row],[楼栋]],INDEX(工单[房号/位置],1):工单[[#This Row],[房号/位置]],工单[[#This Row],[房号/位置]])) -> 1
A37: =IF(OR(工单[[#This Row],[报修日期]]="",工单[[#This Row],[楼栋]]="",工单[[#This Row],[房号/位置]]=""),"待补",IF(工单[[#This Row],[楼栋]]="公共区域","公",IF(工单[[#This Row],[楼栋]]="商铺","S",SUBSTITUTE(工单[[#This Row],[楼栋]],"栋","")))&"-"&工单[[#This Row],[房号/位置]]&"-"&TEXT(MONTH(工单[[#This Row],[报修日期]]),"00")&TEXT(DAY(工单[[#This Row],[报修日期]]),"00")&IF(N(工单[[#This Row],[该户第几次]])>1,"-"&TEXT(工单[[#This Row],[该户第几次]],"00"),"")) -> 公-健身房旁-0501 | B37: 45778 | C37: 公区 | D37: 公共区域 | E37: 健身房旁 | F37: 配电箱附近有电流声 | G37: 电气照明 | H37: 张师傅 | J37: 5月1日 11:10 | L37: 已完成 | N37: =IF(工单[[#This Row],[报修日期]]="","",IF(工单[[#This Row],[完成情况]]="已完成",IF(工单[[#This Row],[完成日期]]="","",工单[[#This Row],[完成日期]]-工单[[#This Row],[报修日期]]),IF(基准日<工单[[#This Row],[报修日期]],"",基准日-工单[[#This Row],[报修日期]]))) | O37: =IF(OR(工单[[#This Row],[楼栋]]="",工单[[#This Row],[房号/位置]]=""),"",COUNTIFS(INDEX(工单[楼栋],1):工单[[#This Row],[楼栋]],工单[[#This Row],[楼栋]],INDEX(工单[房号/位置],1):工单[[#This Row],[房号/位置]],工单[[#This Row],[房号/位置]])) -> 1 | P37: 现场检测未发现异常
A38: =IF(OR(工单[[#This Row],[报修日期]]="",工单[[#This Row],[楼栋]]="",工单[[#This Row],[房号/位置]]=""),"待补",IF(工单[[#This Row],[楼栋]]="公共区域","公",IF(工单[[#This Row],[楼栋]]="商铺","S",SUBSTITUTE(工单[[#This Row],[楼栋]],"栋","")))&"-"&工单[[#This Row],[房号/位置]]&"-"&TEXT(MONTH(工单[[#This Row],[报修日期]]),"00")&TEXT(DAY(工单[[#This Row],[报修日期]]),"00")&IF(N(工单[[#This Row],[该户第几次]])>1,"-"&TEXT(工单[[#This Row],[该户第几次]],"00"),"")) -> 2-1楼-0501 | B38: 45778 | C38: 公区 | D38: 2栋 | E38: 1楼 | F38: 单元门禁读卡器升级更换 | G38: 弱电门禁 | H38: 陈师傅 | I38: 王师傅 | J38: 5月1日 17:00 | L38: 已完成 | N38: =IF(工单[[#This Row],[报修日期]]="","",IF(工单[[#This Row],[完成情况]]="已完成",IF(工单[[#This Row],[完成日期]]="","",工单[[#This Row],[完成日期]]-工单[[#This Row],[报修日期]]),IF(基准日<工单[[#This Row],[报修日期]],"",基准日-工单[[#This Row],[报修日期]]))) | O38: =IF(OR(工单[[#This Row],[楼栋]]="",工单[[#This Row],[房号/位置]]=""),"",COUNTIFS(INDEX(工单[楼栋],1):工单[[#This Row],[楼栋]],工单[[#This Row],[楼栋]],INDEX(工单[房号/位置],1):工单[[#This Row],[房号/位置]],工单[[#This Row],[房号/位置]])) -> 1
A39: =IF(OR(工单[[#This Row],[报修日期]]="",工单[[#This Row],[楼栋]]="",工单[[#This Row],[房号/位置]]=""),"待补",IF(工单[[#This Row],[楼栋]]="公共区域","公",IF(工单[[#This Row],[楼栋]]="商铺","S",SUBSTITUTE(工单[[#This Row],[楼栋]],"栋","")))&"-"&工单[[#This Row],[房号/位置]]&"-"&TEXT(MONTH(工单[[#This Row],[报修日期]]),"00")&TEXT(DAY(工单[[#This Row],[报修日期]]),"00")&IF(N(工单[[#This Row],[该户第几次]])>1,"-"&TEXT(工单[[#This Row],[该户第几次]],"00"),"")) -> 公-东大门-0501-02 | B39: 45778 | C39: 公区 | D39: 公共区域 | E39: 东大门 | F39: 门岗天花受潮破损修缮 | G39: 墙地饰面 | H39: 刘师傅 | J39: 5月1日 | L39: 跟进中 | N39: =IF(工单[[#This Row],[报修日期]]="","",IF(工单[[#This Row],[完成情况]]="已完成",IF(工单[[#This Row],[完成日期]]="","",工单[[#This Row],[完成日期]]-工单[[#This Row],[报修日期]]),IF(基准日<工单[[#This Row],[报修日期]],"",基准日-工单[[#This Row],[报修日期]]))) -> 6 | O39: =IF(OR(工单[[#This Row],[楼栋]]="",工单[[#This Row],[房号/位置]]=""),"",COUNTIFS(INDEX(工单[楼栋],1):工单[[#This Row],[楼栋]],工单[[#This Row],[楼栋]],INDEX(工单[房号/位置],1):工单[[#This Row],[房号/位置]],工单[[#This Row],[房号/位置]])) -> 2 | P39: 已补洞批腻子，待干燥后打磨刷乳胶漆
A40: =IF(OR(工单[[#This Row],[报修日期]]="",工单[[#This Row],[楼栋]]="",工单[[#This Row],[房号/位置]]=""),"待补",IF(工单[[#This Row],[楼栋]]="公共区域","公",IF(工单[[#This Row],[楼栋]]="商铺","S",SUBSTITUTE(工单[[#This Row],[楼栋]],"栋","")))&"-"&工单[[#This Row],[房号/位置]]&"-"&TEXT(MONTH(工单[[#This Row],[报修日期]]),"00")&TEXT(DAY(工单[[#This Row],[报修日期]]),"00")&IF(N(工单[[#This Row],[该户第几次]])>1,"-"&TEXT(工单[[#This Row],[该户第几次]],"00"),"")) -> 8-大堂-0501 | B40: 45778 | C40: 公区 | D40: 8栋 | E40: 大堂 | F40: 8栋大堂吊灯部分不亮 | G40: 电气照明 | H40: 陈师傅 | J40: 5月1日 下午 | L40: 已完成 | N40: =IF(工单[[#This Row],[报修日期]]="","",IF(工单[[#This Row],[完成情况]]="已完成",IF(工单[[#This Row],[完成日期]]="","",工单[[#This Row],[完成日期]]-工单[[#This Row],[报修日期]]),IF(基准日<工单[[#This Row],[报修日期]],"",基准日-工单[[#This Row],[报修日期]]))) | O40: =IF(OR(工单[[#This Row],[楼栋]]="",工单[[#This Row],[房号/位置]]=""),"",COUNTIFS(INDEX(工单[楼栋],1):工单[[#This Row],[楼栋]],工单[[#This Row],[楼栋]],INDEX(工单[房号/位置],1):工单[[#This Row],[房号/位置]],工单[[#This Row],[房号/位置]])) -> 1
A41: =IF(OR(工单[[#This Row],[报修日期]]="",工单[[#This Row],[楼栋]]="",工单[[#This Row],[房号/位置]]=""),"待补",IF(工单[[#This Row],[楼栋]]="公共区域","公",IF(工单[[#This Row],[楼栋]]="商铺","S",SUBSTITUTE(工单[[#This Row],[楼栋]],"栋","")))&"-"&工单[[#This Row],[房号/位置]]&"-"&TEXT(MONTH(工单[[#This Row],[报修日期]]),"00")&TEXT(DAY(工单[[#This Row],[报修日期]]),"00")&IF(N(工单[[#This Row],[该户第几次]])>1,"-"&TEXT(工单[[#This Row],[该户第几次]],"00"),"")) -> 7-凉亭-0501 | B41: 45778 | C41: 公区 | D41: 7栋 | E41: 凉亭 | F41: 凉亭顶部雨后积水不退 | G41: 给排水 | H41: 陈师傅 | I41: 王师傅 | J41: 5月1日 下午 | L41: 跟进中 | N41: =IF(工单[[#This Row],[报修日期]]="","",IF(工单[[#This Row],[完成情况]]="已完成",IF(工单[[#This Row],[完成日期]]="","",工单[[#This Row],[完成日期]]-工单[[#This Row],[报修日期]]),IF(基准日<工单[[#This Row],[报修日期]],"",基准日-工单[[#This Row],[报修日期]]))) -> 6 | O41: =IF(OR(工单[[#This Row],[楼栋]]="",工单[[#This Row],[房号/位置]]=""),"",COUNTIFS(INDEX(工单[楼栋],1):工单[[#This Row],[楼栋]],工单[[#This Row],[楼栋]],INDEX(工单[房号/位置],1):工单[[#This Row],[房号/位置]],工单[[#This Row],[房号/位置]])) -> 1 | P41: 雨水管被落叶堵死，预计重新改管道
...

Sheet 仪表盘
A1: 数据仪表盘 ｜ 入户＋公区 | I1: 数据来自【工单台账】，打开即刷新
A2: 统计基准日 | B2: =基准日 -> 45784 | D2: 统计周期 | E2: 本月 | F2: =" "&TEXT(期初,"yyyy-mm-dd")&" ~ "&TEXT(期末,"yyyy-mm-dd")&" 米黄格可改；基准日在【设置】里改，留空即今天" -> 2025-05-01 ~ 2025-05-31 米黄格可改；基准日在【设置】里改，留空即今天
A4: 一、现在要处理的事
A5: 未结工单 | C5: 其中超期 | E5: 重复报修户 | G5: 空闲师傅 | I5: 今日休息
A6: =COUNTIFS(工单[完成情况],"<>已完成",工单[报修问题描述],"<>") -> 19 | C6: =SUMPRODUCT((工单[完成情况]<>"已完成")*ISNUMBER(工单[处理天数])*((0&工单[处理天数])*1>=超期阈值)) -> 17 | E6: =COUNTIFS(工单[该户第几次],2) -> 5 | G6: =COUNTIF(工单台账!$H$4:$L$4,"空闲") -> 0 | I6: =COUNTIF(工单台账!$H$4:$L$4,"休息") -> 1
A7: 跟进中 / 需另约 / 没填状态 | C7: ="等待 ≥ "&超期阈值&" 天" -> 等待 ≥ 3 天 | E7: 同一户 / 同一位置 ≥ 2 次 | G7: 上班且手上没有跟进中的单 | I7: 在【工单台账】顶部设置
A9: ="未结工单（按等待天数从长到短，最多列 15 单） 共 "&A6&" 单" -> 未结工单（按等待天数从长到短，最多列 15 单） 共 19 单
A10: 单据编号 | B10: 类型 | C10: 楼栋 | D10: 房号/位置 | E10: 报修问题描述 | H10: 维修类别 | I10: 跟进人 | J10: 报修日期 | K10: 等待天数 | L10: 完成情况 | M10: 最新进展
A11: =IF($P11=0,"",INDEX(工单[单据编号],$P11-ROW(工单[#Headers]))&"") -> 7-凉亭-0501 | B11: =IF($P11=0,"",INDEX(工单[类型],$P11-ROW(工单[#Headers]))&"") -> 公区 | C11: =IF($P11=0,"",INDEX(工单[楼栋],$P11-ROW(工单[#Headers]))&"") -> 7栋 | D11: =IF($P11=0,"",INDEX(工单[房号/位置],$P11-ROW(工单[#Headers]))&"") -> 凉亭 | E11: =IF($P11=0,"",INDEX(工单[报修问题描述],$P11-ROW(工单[#Headers]))&"") -> 凉亭顶部雨后积水不退 | H11: =IF($P11=0,"",INDEX(工单[维修类别],$P11-ROW(工单[#Headers]))&"") -> 给排水 | I11: =IF($P11=0,"",INDEX(工单[跟进人1],$P11-ROW(工单[#Headers]))&IF(INDEX(工单[跟进人2],$P11-ROW(工单[#Headers]))="","","、"&INDEX(工单[跟进人2],$P11-ROW(工单[#Headers])))) -> 陈师傅、王师傅 | J11: =IF($P11=0,"",INDEX(工单[报修日期],$P11-ROW(工单[#Headers]))) -> 45778 | K11: =IF($P11=0,"",INDEX(工单[处理天数],$P11-ROW(工单[#Headers]))) -> 6 | L11: =IF($P11=0,"",IF(INDEX(工单[完成情况],$P11-ROW(工单[#Headers]))="","没填状态",INDEX(工单[完成情况],$P11-ROW(工单[#Headers])))) -> 跟进中 | M11: =IF($P11=0,"",INDEX(工单[维修备注],$P11-ROW(工单[#Headers]))&"") -> 雨水管被落叶堵死，预计重新改管道 | P11: =IFERROR(MOD(SUMPRODUCT(LARGE((工单[完成情况]<>"已完成")*ISNUMBER(工单[处理天数])*((0&工单[处理天数])*100000+ROW(工单[处理天数])),1)),100000),0) -> 41
A12: =IF($P12=0,"",INDEX(工单[单据编号],$P12-ROW(工单[#Headers]))&"") -> 公-东大门-0501-02 | B12: =IF($P12=0,"",INDEX(工单[类型],$P12-ROW(工单[#Headers]))&"") -> 公区 | C12: =IF($P12=0,"",INDEX(工单[楼栋],$P12-ROW(工单[#Headers]))&"") -> 公共区域 | D12: =IF($P12=0,"",INDEX(工单[房号/位置],$P12-ROW(工单[#Headers]))&"") -> 东大门 | E12: =IF($P12=0,"",INDEX(工单[报修问题描述],$P12-ROW(工单[#Headers]))&"") -> 门岗天花受潮破损修缮 | H12: =IF($P12=0,"",INDEX(工单[维修类别],$P12-ROW(工单[#Headers]))&"") -> 墙地饰面 | I12: =IF($P12=0,"",INDEX(工单[跟进人1],$P12-ROW(工单[#Headers]))&IF(INDEX(工单[跟进人2],$P12-ROW(工单[#Headers]))="","","、"&INDEX(工单[跟进人2],$P12-ROW(工单[#Headers])))) -> 刘师傅 | J12: =IF($P12=0,"",INDEX(工单[报修日期],$P12-ROW(工单[#Headers]))) -> 45778 | K12: =IF($P12=0,"",INDEX(工单[处理天数],$P12-ROW(工单[#Headers]))) -> 6 | L12: =IF($P12=0,"",IF(INDEX(工单[完成情况],$P12-ROW(工单[#Headers]))="","没填状态",INDEX(工单[完成情况],$P12-ROW(工单[#Headers])))) -> 跟进中 | M12: =IF($P12=0,"",INDEX(工单[维修备注],$P12-ROW(工单[#Headers]))&"") -> 已补洞批腻子，待干燥后打磨刷乳胶漆 | P12: =IFERROR(MOD(SUMPRODUCT(LARGE((工单[完成情况]<>"已完成")*ISNUMBER(工单[处理天数])*((0&工单[处理天数])*100000+ROW(工单[处理天数])),2)),100000),0) -> 39
A13: =IF($P13=0,"",INDEX(工单[单据编号],$P13-ROW(工单[#Headers]))&"") -> 9-肉菜市场-0501 | B13: =IF($P13=0,"",INDEX(工单[类型],$P13-ROW(工单[#Headers]))&"") -> 公区 | C13: =IF($P13=0,"",INDEX(工单[楼栋],$P13-ROW(工单[#Headers]))&"") -> 9栋 | D13: =IF($P13=0,"",INDEX(工单[房号/位置],$P13-ROW(工单[#Headers]))&"") -> 肉菜市场 | E13: =IF($P13=0,"",INDEX(工单[报修问题描述],$P13-ROW(工单[#Headers]))&"") -> 市场内墙雨后渗水 | H13: =IF($P13=0,"",INDEX(工单[维修类别],$P13-ROW(工单[#Headers]))&"") -> 渗漏防水 | I13: =IF($P13=0,"",INDEX(工单[跟进人1],$P13-ROW(工单[#Headers]))&IF(INDEX(工单[跟进人2],$P13-ROW(工单[#Headers]))="","","、"&INDEX(工单[跟进人2],$P13-ROW(工单[#Headers])))) -> 刘师傅 | J13: =IF($P13=0,"",INDEX(工单[报修日期],$P13-ROW(工单[#Headers]))) -> 45778 | K13: =IF($P13=0,"",INDEX(工单[处理天数],$P13-ROW(工单[#Headers]))) -> 6 | L13: =IF($P13=0,"",IF(INDEX(工单[完成情况],$P13-ROW(工单[#Headers]))="","没填状态",INDEX(工单[完成情况],$P13-ROW(工单[#Headers])))) -> 跟进中 | M13: =IF($P13=0,"",INDEX(工单[维修备注],$P13-ROW(工单[#Headers]))&"") -> 待跟进 | P13: =IFERROR(MOD(SUMPRODUCT(LARGE((工单[完成情况]<>"已完成")*ISNUMBER(工单[处理天数])*((0&工单[处理天数])*100000+ROW(工单[处理天数])),3)),100000),0) -> 35
A14: =IF($P14=0,"",INDEX(工单[单据编号],$P14-ROW(工单[#Headers]))&"") -> 8-1602-0501 | B14: =IF($P14=0,"",INDEX(工单[类型],$P14-ROW(工单[#Headers]))&"") -> 入户 | C14: =IF($P14=0,"",INDEX(工单[楼栋],$P14-ROW(工单[#Headers]))&"") -> 8栋 | D14: =IF($P14=0,"",INDEX(工单[房号/位置],$P14-ROW(工单[#Headers]))&"") -> 1602 | E14: =IF($P14=0,"",INDEX(工单[报修问题描述],$P14-ROW(工单[#Headers]))&"") -> 客厅空调管冷凝水滴落 | H14: =IF($P14=0,"",INDEX(工单[维修类别],$P14-ROW(工单[#Headers]))&"") -> 空调暖通 | I14: =IF($P14=0,"",INDEX(工单[跟进人1],$P14-ROW(工单[#Headers]))&IF(INDEX(工单[跟进人2],$P14-ROW(工单[#Headers]))="","","、"&INDEX(工单[跟进人2],$P14-ROW(工单[#Headers])))) | J14: =IF($P14=0,"",INDEX(工单[报修日期],$P14-ROW(工单[#Headers]))) -> 45778 | K14: =IF($P14=0,"",INDEX(工单[处理天数],$P14-ROW(工单[#Headers]))) -> 6 | L14: =IF($P14=0,"",IF(INDEX(工单[完成情况],$P14-ROW(工单[#Headers]))="","没填状态",INDEX(工单[完成情况],$P14-ROW(工单[#Headers])))) -> 跟进中 | M14: =IF($P14=0,"",INDEX(工单[维修备注],$P14-ROW(工单[#Headers]))&"") -> 需先由第三方单位为楼上住户空调管加装保温棉 | P14: =IFERROR(MOD(SUMPRODUCT(LARGE((工单[完成情况]<>"已完成")*ISNUMBER(工单[处理天数])*((0&工单[处理天数])*100000+ROW(工单[处理天数])),4)),100000),0) -> 14
A15: =IF($P15=0,"",INDEX(工单[单据编号],$P15-ROW(工单[#Headers]))&"") -> 6-701-0501 | B15: =IF($P15=0,"",INDEX(工单[类型],$P15-ROW(工单[#Headers]))&"") -> 入户 | C15: =IF($P15=0,"",INDEX(工单[楼栋],$P15-ROW(工单[#Headers]))&"") -> 6栋 | D15: =IF($P15=0,"",INDEX(工单[房号/位置],$P15-ROW(工单[#Headers]))&"") -> 701 | E15: =IF($P15=0,"",INDEX(工单[报修问题描述],$P15-ROW(工单[#Headers]))&"") -> 次卧墙面受潮鼓包起皮 | H15: =IF($P15=0,"",INDEX(工单[维修类别],$P15-ROW(工单[#Headers]))&"") -> 墙地饰面 | I15: =IF($P15=0,"",INDEX(工单[跟进人1],$P15-ROW(工单[#Headers]))&IF(INDEX(工单[跟进人2],$P15-ROW(工单[#Headers]))="","","、"&INDEX(工单[跟进人2],$P15-ROW(工单[#Headers])))) -> 李师傅 | J15: =IF($P15=0,"",INDEX(工单[报修日期],$P15-ROW(工单[#Headers]))) -> 45778 | K15: =IF($P15=0,"",INDEX(工单[处理天数],$P15-ROW(工单[#Headers]))) -> 6 | L15: =IF($P15=0,"",IF(INDEX(工单[完成情况],$P15-ROW(工单[#Headers]))="","没填状态",INDEX(工单[完成情况],$P15-ROW(工单[#Headers])))) -> 跟进中 | M15: =IF($P15=0,"",INDEX(工单[维修备注],$P15-ROW(工单[#Headers]))&"") -> 已铲除鼓包批第一遍腻子，待干透后约第二次上门 | P15: =IFERROR(MOD(SUMPRODUCT(LARGE((工单[完成情况]<>"已完成")*ISNUMBER(工单[处理天数])*((0&工单[处理天数])*100000+ROW(工单[处理天数])),5)),100000),0) -> 13
A16: =IF($P16=0,"",INDEX(工单[单据编号],$P16-ROW(工单[#Headers]))&"") -> 6-2504-0501 | B16: =IF($P16=0,"",INDEX(工单[类型],$P16-ROW(工单[#Headers]))&"") -> 入户 | C16: =IF($P16=0,"",INDEX(工单[楼栋],$P16-ROW(工单[#Headers]))&"") -> 6栋 | D16: =IF($P16=0,"",INDEX(工单[房号/位置],$P16-ROW(工单[#Headers]))&"") -> 2504 | E16: =IF($P16=0,"",INDEX(工单[报修问题描述],$P16-ROW(工单[#Headers]))&"") -> 空调开机后室内机滴水 | H16: =IF($P16=0,"",INDEX(工单[维修类别],$P16-ROW(工单[#Headers]))&"") -> 空调暖通 | I16: =IF($P16=0,"",INDEX(工单[跟进人1],$P16-ROW(工单[#Headers]))&IF(INDEX(工单[跟进人2],$P16-ROW(工单[#Headers]))="","","、"&INDEX(工单[跟进人2],$P16-ROW(工单[#Headers])))) -> 刘师傅、张师傅 | J16: =IF($P16=0,"",INDEX(工单[报修日期],$P16-ROW(工单[#Headers]))) -> 45778 | K16: =IF($P16=0,"",INDEX(工单[处理天数],$P16-ROW(工单[#Headers]))) -> 6 | L16: =IF($P16=0,"",IF(INDEX(工单[完成情况],$P16-ROW(工单[#Headers]))="","没填状态",INDEX(工单[完成情况],$P16-ROW(工单[#Headers])))) -> 跟进中 | M16: =IF($P16=0,"",INDEX(工单[维修备注],$P16-ROW(工单[#Headers]))&"") -> 需重新包扎保温棉，待料处理 | P16: =IFERROR(MOD(SUMPRODUCT(LARGE((工单[完成情况]<>"已完成")*ISNUMBER(工单[处理天数])*((0&工单[处理天数])*100000+ROW(工单[处理天数])),6)),100000),0) -> 8
A17: =IF($P17=0,"",INDEX(工单[单据编号],$P17-ROW(工单[#Headers]))&"") -> 7-1301-0502 | B17: =IF($P17=0,"",INDEX(工单[类型],$P17-ROW(工单[#Headers]))&"") -> 入户 | C17: =IF($P17=0,"",INDEX(工单[楼栋],$P17-ROW(工单[#Headers]))&"") -> 7栋 | D17: =IF($P17=0,"",INDEX(工单[房号/位置],$P17-ROW(工单[#Headers]))&"") -> 1301 | E17: =IF($P17=0,"",INDEX(工单[报修问题描述],$P17-ROW(工单[#Headers]))&"") -> 卧室墙面出现细小裂纹 | H17: =IF($P17=0,"",INDEX(工单[维修类别],$P17-ROW(工单[#Headers]))&"") -> 墙地饰面 | I17: =IF($P17=0,"",INDEX(工单[跟进人1],$P17-ROW(工单[#Headers]))&IF(INDEX(工单[跟进人2],$P17-ROW(工单[#Headers]))="","","、"&INDEX(工单[跟进人2],$P17-ROW(工单[#Headers])))) -> 李师傅 | J17: =IF($P17=0,"",INDEX(工单[报修日期],$P17-ROW(工单[#Headers]))) -> 45779 | K17: =IF($P17=0,"",INDEX(工单[处理天数],$P17-ROW(工单[#Headers]))) -> 5 | L17: =IF($P17=0,"",IF(INDEX(工单[完成情况],$P17-ROW(工单[#Headers]))="","没填状态",INDEX(工单[完成情况],$P17-ROW(工单[#Headers])))) -> 跟进中 | M17: =IF($P17=0,"",INDEX(工单[维修备注],$P17-ROW(工单[#Headers]))&"") -> 已现场查看，待腻子干透后打磨修补 | P17: =IFERROR(MOD(SUMPRODUCT(LARGE((工单[完成情况]<>"已完成")*ISNUMBER(工单[处理天数])*((0&工单[处理天数])*100000+ROW(工单[处理天数])),7)),100000),0) -> 61
A18: =IF($P18=0,"",INDEX(工单[单据编号],$P18-ROW(工单[#Headers]))&"") -> 5-1501-0502 | B18: =IF($P18=0,"",INDEX(工单[类型],$P18-ROW(工单[#Headers]))&"") -> 入户 | C18: =IF($P18=0,"",INDEX(工单[楼栋],$P18-ROW(工单[#Headers]))&"") -> 5栋 | D18: =IF($P18=0,"",INDEX(工单[房号/位置],$P18-ROW(工单[#Headers]))&"") -> 1501 | E18: =IF($P18=0,"",INDEX(工单[报修问题描述],$P18-ROW(工单[#Headers]))&"") -> 主卧外墙渗水，墙纸发霉 | H18: =IF($P18=0,"",INDEX(工单[维修类别],$P18-ROW(工单[#Headers]))&"") -> 渗漏防水 | I18: =IF($P18=0,"",INDEX(工单[跟进人1],$P18-ROW(工单[#Headers]))&IF(INDEX(工单[跟进人2],$P18-ROW(工单[#Headers]))="","","、"&INDEX(工单[跟进人2],$P18-ROW(工单[#Headers])))) -> 陈师傅 | J18: =IF($P18=0,"",INDEX(工单[报修日期],$P18-ROW(工单[#Headers]))) -> 45779 | K18: =IF($P18=0,"",INDEX(工单[处理天数],$P18-ROW(工单[#Headers]))) -> 5 | L18: =IF($P18=0,"",IF(INDEX(工单[完成情况],$P18-ROW(工单[#Headers]))="","没填状态",INDEX(工单[完成情况],$P18-ROW(工单[#Headers])))) -> 跟进中 | M18: =IF($P18=0,"",INDEX(工单[维修备注],$P18-ROW(工单[#Headers]))&"") -> 已现场拍照留证，待后续协商处理（业主意向使用公共维修资金） | P18: =IFERROR(MOD(SUMPRODUCT(LARGE((工单[完成情况]<>"已完成")*ISNUMBER(工单[处理天数])*((0&工单[处理天数])*100000+ROW(工单[处理天数])),8)),100000),0) -> 51
A19: =IF($P19=0,"",INDEX(工单[单据编号],$P19-ROW(工单[#Headers]))&"") -> 6-3304-0502 | B19: =IF($P19=0,"",INDEX(工单[类型],$P19-ROW(工单[#Headers]))&"") -> 入户 | C19: =IF($P19=0,"",INDEX(工单[楼栋],$P19-ROW(工单[#Headers]))&"") -> 6栋 | D19: =IF($P19=0,"",INDEX(工单[房号/位置],$P19-ROW(工单[#Headers]))&"") -> 3304 | E19: =IF($P19=0,"",INDEX(工单[报修问题描述],$P19-ROW(工单[#Headers]))&"") -> 空调外机噪音大 | H19: =IF($P19=0,"",INDEX(工单[维修类别],$P19-ROW(工单[#Headers]))&"") -> 空调暖通 | I19: =IF($P19=0,"",INDEX(工单[跟进人1],$P19-ROW(工单[#Headers]))&IF(INDEX(工单[跟进人2],$P19-ROW(工单[#Headers]))="","","、"&INDEX(工单[跟进人2],$P19-ROW(工单[#Headers])))) -> 李师傅 | J19: =IF($P19=0,"",INDEX(工单[报修日期],$P19-ROW(工单[#Headers]))) -> 45779 | K19: =IF($P19=0,"",INDEX(工单[处理天数],$P19-ROW(工单[#Headers]))) -> 5 | L19: =IF($P19=0,"",IF(INDEX(工单[完成情况],$P19-ROW(工单[#Headers]))="","没填状态",INDEX(工单[完成情况],$P19-ROW(工单[#Headers])))) -> 跟进中 | M19: =IF($P19=0,"",INDEX(工单[维修备注],$P19-ROW(工单[#Headers]))&"") -> 非物业维修范围，业主已联系空调售后 | P19: =IFERROR(MOD(SUMPRODUCT(LARGE((工单[完成情况]<>"已完成")*ISNUMBER(工单[处理天数])*((0&工单[处理天数])*100000+ROW(工单[处理天数])),9)),100000),0) -> 48
A20: =IF($P20=0,"",INDEX(工单[单据编号],$P20-ROW(工单[#Headers]))&"") -> 5-1602-0502 | B20: =IF($P20=0,"",INDEX(工单[类型],$P20-ROW(工单[#Headers]))&"") -> 入户 | C20: =IF($P20=0,"",INDEX(工单[楼栋],$P20-ROW(工单[#Headers]))&"") -> 5栋 | D20: =IF($P20=0,"",INDEX(工单[房号/位置],$P20-ROW(工单[#Headers]))&"") -> 1602 | E20: =IF($P20=0,"",INDEX(工单[报修问题描述],$P20-ROW(工单[#Headers]))&"") -> 次卧外墙窗边渗水 | H20: =IF($P20=0,"",INDEX(工单[维修类别],$P20-ROW(工单[#Headers]))&"") -> 渗漏防水 | I20: =IF($P20=0,"",INDEX(工单[跟进人1],$P20-ROW(工单[#Headers]))&IF(INDEX(工单[跟进人2],$P20-ROW(工单[#Headers]))="","","、"&INDEX(工单[跟进人2],$P20-ROW(工单[#Headers])))) -> 李师傅 | J20: =IF($P20=0,"",INDEX(工单[报修日期],$P20-ROW(工单[#Headers]))) -> 45779 | K20: =IF($P20=0,"",INDEX(工单[处理天数],$P20-ROW(工单[#Headers]))) -> 5 | L20: =IF($P20=0,"",IF(INDEX(工单[完成情况],$P20-ROW(工单[#Headers]))="","没填状态",INDEX(工单[完成情况],$P20-ROW(工单[#Headers])))) -> 跟进中 | M20: =IF($P20=0,"",INDEX(工单[维修备注],$P20-ROW(工单[#Headers]))&"") -> 已查看，业主要求先处理室内墙面，再排查渗水点并尽快修复 | P20: =IFERROR(MOD(SUMPRODUCT(LARGE((工单[完成情况]<>"已完成")*ISNUMBER(工单[处理天数])*((0&工单[处理天数])*100000+ROW(工单[处理天数])),10)),100000),0) -> 42
A21: =IF($P21=0,"",INDEX(工单[单据编号],$P21-ROW(工单[#Headers]))&"") -> 公-254车位-0503 | B21: =IF($P21=0,"",INDEX(工单[类型],$P21-ROW(工单[#Headers]))&"") -> 公区 | C21: =IF($P21=0,"",INDEX(工单[楼栋],$P21-ROW(工单[#Headers]))&"") -> 公共区域 | D21: =IF($P21=0,"",INDEX(工单[房号/位置],$P21-ROW(工单[#Headers]))&"") -> 254车位 | E21: =IF($P21=0,"",INDEX(工单[报修问题描述],$P21-ROW(工单[#Headers]))&"") -> 车位顶板漏水 | H21: =IF($P21=0,"",INDEX(工单[维修类别],$P21-ROW(工单[#Headers]))&"") -> 渗漏防水 | I21: =IF($P21=0,"",INDEX(工单[跟进人1],$P21-ROW(工单[#Headers]))&IF(INDEX(工单[跟进人2],$P21-ROW(工单[#Headers]))="","","、"&INDEX(工单[跟进人2],$P21-ROW(工单[#Headers])))) | J21: =IF($P21=0,"",INDEX(工单[报修日期],$P21-ROW(工单[#Headers]))) -> 45780 | K21: =IF($P21=0,"",INDEX(工单[处理天数],$P21-ROW(工单[#Headers]))) -> 4 | L21: =IF($P21=0,"",IF(INDEX(工单[完成情况],$P21-ROW(工单[#Headers]))="","没填状态",INDEX(工单[完成情况],$P21-ROW(工单[#Headers])))) -> 没填状态 | M21: =IF($P21=0,"",INDEX(工单[维修备注],$P21-ROW(工单[#Headers]))&"") | P21: =IFERROR(MOD(SUMPRODUCT(LARGE((工单[完成情况]<>"已完成")*ISNUMBER(工单[处理天数])*((0&工单[处理天数])*100000+ROW(工单[处理天数])),11)),100000),0) -> 96
A22: =IF($P22=0,"",INDEX(工单[单据编号],$P22-ROW(工单[#Headers]))&"") -> 6-2802-0503 | B22: =IF($P22=0,"",INDEX(工单[类型],$P22-ROW(工单[#Headers]))&"") -> 入户 | C22: =IF($P22=0,"",INDEX(工单[楼栋],$P22-ROW(工单[#Headers]))&"") -> 6栋 | D22: =IF($P22=0,"",INDEX(工单[房号/位置],$P22-ROW(工单[#Headers]))&"") -> 2802 | E22: =IF($P22=0,"",INDEX(工单[报修问题描述],$P22-ROW(工单[#Headers]))&"") -> 连续下雨后阳台墙面渗水 | H22: =IF($P22=0,"",INDEX(工单[维修类别],$P22-ROW(工单[#Headers]))&"") -> 渗漏防水 | I22: =IF($P22=0,"",INDEX(工单[跟进人1],$P22-ROW(工单[#Headers]))&IF(INDEX(工单[跟进人2],$P22-ROW(工单[#Headers]))="","","、"&INDEX(工单[跟进人2],$P22-ROW(工单[#Headers])))) -> 陈师傅 | J22: =IF($P22=0,"",INDEX(工单[报修日期],$P22-ROW(工单[#Headers]))) -> 45780 | K22: =IF($P22=0,"",INDEX(工单[处理天数],$P22-ROW(工单[#Headers]))) -> 4 | L22: =IF($P22=0,"",IF(INDEX(工单[完成情况],$P22-ROW(工单[#Headers]))="","没填状态",INDEX(工单[完成情况],$P22-ROW(工单[#Headers])))) -> 跟进中 | M22: =IF($P22=0,"",INDEX(工单[维修备注],$P22-ROW(工单[#Headers]))&"") -> 已拍照留证，待联系防水单位复查 | P22: =IFERROR(MOD(SUMPRODUCT(LARGE((工单[完成情况]<>"已完成")*ISNUMBER(工单[处理天数])*((0&工单[处理天数])*100000+ROW(工单[处理天数])),12)),100000),0) -> 95
A23: =IF($P23=0,"",INDEX(工单[单据编号],$P23-ROW(工单[#Headers]))&"") -> 7-3002-0503 | B23: =IF($P23=0,"",INDEX(工单[类型],$P23-ROW(工单[#Headers]))&"") -> 入户 | C23: =IF($P23=0,"",INDEX(工单[楼栋],$P23-ROW(工单[#Headers]))&"") -> 7栋 | D23: =IF($P23=0,"",INDEX(工单[房号/位置],$P23-ROW(工单[#Headers]))&"") -> 3002 | E23: =IF($P23=0,"",INDEX(工单[报修问题描述],$P23-ROW(工单[#Headers]))&"") -> 需要加装插座并固定门把手 | H23: =IF($P23=0,"",INDEX(工单[维修类别],$P23-ROW(工单[#Headers]))&"") -> 电气照明 | I23: =IF($P23=0,"",INDEX(工单[跟进人1],$P23-ROW(工单[#Headers]))&IF(INDEX(工单[跟进人2],$P23-ROW(工单[#Headers]))="","","、"&INDEX(工单[跟进人2],$P23-ROW(工单[#Headers])))) -> 张师傅 | J23: =IF($P23=0,"",INDEX(工单[报修日期],$P23-ROW(工单[#Headers]))) -> 45780 | K23: =IF($P23=0,"",INDEX(工单[处理天数],$P23-ROW(工单[#Headers]))) -> 4 | L23: =IF($P23=0,"",IF(INDEX(工单[完成情况],$P23-ROW(工单[#Headers]))="","没填状态",INDEX(工单[完成情况],$P23-ROW(工单[#Headers])))) -> 跟进中 | M23: =IF($P23=0,"",INDEX(工单[维修备注],$P23-ROW(工单[#Headers]))&"") -> 门把手已固定，插座待业主买好面板后再约时间 | P23: =IFERROR(MOD(SUMPRODUCT(LARGE((工单[完成情况]<>"已完成")*ISNUMBER(工单[处理天数])*((0&工单[处理天数])*100000+ROW(工单[处理天数])),13)),100000),0) -> 78
A24: =IF($P24=0,"",INDEX(工单[单据编号],$P24-ROW(工单[#Headers]))&"") -> 5-货梯-0504 | B24: =IF($P24=0,"",INDEX(工单[类型],$P24-ROW(工单[#Headers]))&"") -> 公区 | C24: =IF($P24=0,"",INDEX(工单[楼栋],$P24-ROW(工单[#Headers]))&"") -> 5栋 | D24: =IF($P24=0,"",INDEX(工单[房号/位置],$P24-ROW(工单[#Headers]))&"") -> 货梯 | E24: =IF($P24=0,"",INDEX(工单[报修问题描述],$P24-ROW(工单[#Headers]))&"") -> 5栋货梯空调不凉 | H24: =IF($P24=0,"",INDEX(工单[维修类别],$P24-ROW(工单[#Headers]))&"") -> 空调暖通 | I24: =IF($P24=0,"",INDEX(工单[跟进人1],$P24-ROW(工单[#Headers]))&IF(INDEX(工单[跟进人2],$P24-ROW(工单[#Headers]))="","","、"&INDEX(工单[跟进人2],$P24-ROW(工单[#Headers])))) | J24: =IF($P24=0,"",INDEX(工单[报修日期],$P24-ROW(工单[#Headers]))) -> 45781 | K24: =IF($P24=0,"",INDEX(工单[处理天数],$P24-ROW(工单[#Headers]))) -> 3 | L24: =IF($P24=0,"",IF(INDEX(工单[完成情况],$P24-ROW(工单[#Headers]))="","没填状态",INDEX(工单[完成情况],$P24-ROW(工单[#Headers])))) -> 没填状态 | M24: =IF($P24=0,"",INDEX(工单[维修备注],$P24-ROW(工单[#Headers]))&"") | P24: =IFERROR(MOD(SUMPRODUCT(LARGE((工单[完成情况]<>"已完成")*ISNUMBER(工单[处理天数])*((0&工单[处理天数])*100000+ROW(工单[处理天数])),14)),100000),0) -> 116
A25: =IF($P25=0,"",INDEX(工单[单据编号],$P25-ROW(工单[#Headers]))&"") -> 11-2904-0504 | B25: =IF($P25=0,"",INDEX(工单[类型],$P25-ROW(工单[#Headers]))&"") -> 入户 | C25: =IF($P25=0,"",INDEX(工单[楼栋],$P25-ROW(工单[#Headers]))&"") -> 11栋 | D25: =IF($P25=0,"",INDEX(工单[房号/位置],$P25-ROW(工单[#Headers]))&"") -> 2904 | E25: =IF($P25=0,"",INDEX(工单[报修问题描述],$P25-ROW(工单[#Headers]))&"") -> 卫生间墙砖空鼓开裂 | H25: =IF($P25=0,"",INDEX(工单[维修类别],$P25-ROW(工单[#Headers]))&"") -> 墙地饰面 | I25: =IF($P25=0,"",INDEX(工单[跟进人1],$P25-ROW(工单[#Headers]))&IF(INDEX(工单[跟进人2],$P25-ROW(工单[#Headers]))="","","、"&INDEX(工单[跟进人2],$P25-ROW(工单[#Headers])))) -> 李师傅 | J25: =IF($P25=0,"",INDEX(工单[报修日期],$P25-ROW(工单[#Headers]))) -> 45781 | K25: =IF($P25=0,"",INDEX(工单[处理天数],$P25-ROW(工单[#Headers]))) -> 3 | L25: =IF($P25=0,"",IF(INDEX(工单[完成情况],$P25-ROW(工单[#Headers]))="","没填状态",INDEX(工单[完成情况],$P25-ROW(工单[#Headers])))) -> 跟进中 | M25: =IF($P25=0,"",INDEX(工单[维修备注],$P25-ROW(工单[#Headers]))&"") -> 待业主确认施工时间后返修 | P25: =IFERROR(MOD(SUMPRODUCT(LARGE((工单[完成情况]<>"已完成")*ISNUMBER(工单[处理天数])*((0&工单[处理天数])*100000+ROW(工单[处理天数])),15)),100000),0) -> 113
A26: =IF(A6>15," 还有 "&(A6-15)&" 单没列出：在台账里筛选「完成情况」查看。"," 没填报修日期的未结单不在这里，台账里会标米黄。") -> 还有 4 单没列出：在台账里筛选「完成情况」查看。
A28: ="重复报修户（按第二次报修时间从近到远，最多列 10 户；≥ 3 次建议主管上门回访） 共 "&E6&" 户" -> 重复报修户（按第二次报修时间从近到远，最多列 10 户；≥ 3 次建议主管上门回访） 共 5 户
A29: 楼栋 | B29: 房号/位置 | C29: 累计次数 | D29: 最近报修 | E29: 最近一次问题 | H29: 维修类别 | I29: 跟进人 | J29: 完成情况 | K29: 维修评价 | L29: 维修备注
A30: =IF($Q30=0,"",INDEX(工单[楼栋],$Q30-ROW(工单[#Headers]))&"") -> 6栋 | B30: =IF($Q30=0,"",INDEX(工单[房号/位置],$Q30-ROW(工单[#Headers]))&"") -> 504 | C30: =IF($Q30=0,"",COUNTIFS(工单[楼栋],A30,工单[房号/位置],B30)) -> 2 | D30: =IF($Q30=0,"",INDEX(工单[报修日期],$Q30-ROW(工单[#Headers]))) -> 45784 | E30: =IF($Q30=0,"",INDEX(工单[报修问题描述],$Q30-ROW(工单[#Headers]))&"") -> 燃气灶点火打不着 | H30: =IF($Q30=0,"",INDEX(工单[维修类别],$Q30-ROW(工单[#Headers]))&"") -> 燃气厨电 | I30: =IF($Q30=0,"",INDEX(工单[跟进人1],$Q30-ROW(工单[#Headers]))&"") -> 张师傅 | J30: =IF($Q30=0,"",INDEX(工单[完成情况],$Q30-ROW(工单[#Headers]))&"") -> 已完成 | K30: =IF($Q30=0,"",INDEX(工单[维修评价],$Q30-ROW(工单[#Headers]))&"") -> 非常满意 | L30: =IF($Q30=0,"",INDEX(工单[维修备注],$Q30-ROW(工单[#Headers]))&"") | P30: =IFERROR(SUMPRODUCT(LARGE((工单[该户第几次]=2)*ROW(工单[该户第几次]),1)),0) -> 139 | Q30: =IF(P30=0,0,SUMPRODUCT(MAX((工单[楼栋]=INDEX(工单[楼栋],P30-ROW(工单[#Headers])))*(工单[房号/位置]=INDEX(工单[房号/位置],P30-ROW(工单[#Headers])))*ROW(工单[楼栋])))) -> 139
A31: =IF($Q31=0,"",INDEX(工单[楼栋],$Q31-ROW(工单[#Headers]))&"") -> 8栋 | B31: =IF($Q31=0,"",INDEX(工单[房号/位置],$Q31-ROW(工单[#Headers]))&"") -> 1501 | C31: =IF($Q31=0,"",COUNTIFS(工单[楼栋],A31,工单[房号/位置],B31)) -> 3 | D31: =IF($Q31=0,"",INDEX(工单[报修日期],$Q31-ROW(工单[#Headers]))) -> 45784 | E31: =IF($Q31=0,"",INDEX(工单[报修问题描述],$Q31-ROW(工单[#Headers]))&"") -> 想挂电视需要打孔 | H31: =IF($Q31=0,"",INDEX(工单[维修类别],$Q31-ROW(工单[#Headers]))&"") -> 其他 | I31: =IF($Q31=0,"",INDEX(工单[跟进人1],$Q31-ROW(工单[#Headers]))&"") -> 张师傅 | J31: =IF($Q31=0,"",INDEX(工单[完成情况],$Q31-ROW(工单[#Headers]))&"") -> 已完成 | K31: =IF($Q31=0,"",INDEX(工单[维修评价],$Q31-ROW(工单[#Headers]))&"") -> 非常满意 | L31: =IF($Q31=0,"",INDEX(工单[维修备注],$Q31-ROW(工单[#Headers]))&"") | P31: =IFERROR(SUMPRODUCT(LARGE((工单[该户第几次]=2)*ROW(工单[该户第几次]),2)),0) -> 132 | Q31: =IF(P31=0,0,SUMPRODUCT(MAX((工单[楼栋]=INDEX(工单[楼栋],P31-ROW(工单[#Headers])))*(工单[房号/位置]=INDEX(工单[房号/位置],P31-ROW(工单[#Headers])))*ROW(工单[楼栋])))) -> 141
A32: =IF($Q32=0,"",INDEX(工单[楼栋],$Q32-ROW(工单[#Headers]))&"") -> 7栋 | B32: =IF($Q32=0,"",INDEX(工单[房号/位置],$Q32-ROW(工单[#Headers]))&"") -> 1304 | C32: =IF($Q32=0,"",COUNTIFS(工单[楼栋],A32,工单[房号/位置],B32)) -> 2 | D32: =IF($Q32=0,"",INDEX(工单[报修日期],$Q32-ROW(工单[#Headers]))) -> 45781 | E32: =IF($Q32=0,"",INDEX(工单[报修问题描述],$Q32-ROW(工单[#Headers]))&"") -> 镜柜铰链到货了，麻烦上门安装 | H32: =IF($Q32=0,"",INDEX(工单[维修类别],$Q32-ROW(工单[#Headers]))&"") -> 门窗五金 | I32: =IF($Q32=0,"",INDEX(工单[跟进人1],$Q32-ROW(工单[#Headers]))&"") -> 张师傅 | J32: =IF($Q32=0,"",INDEX(工单[完成情况],$Q32-ROW(工单[#Headers]))&"") -> 已完成 | K32: =IF($Q32=0,"",INDEX(工单[维修评价],$Q32-ROW(工单[#Headers]))&"") -> 非常满意 | L32: =IF($Q32=0,"",INDEX(工单[维修备注],$Q32-ROW(工单[#Headers]))&"") | P32: =IFERROR(SUMPRODUCT(LARGE((工单[该户第几次]=2)*ROW(工单[该户第几次]),3)),0) -> 105 | Q32: =IF(P32=0,0,SUMPRODUCT(MAX((工单[楼栋]=INDEX(工单[楼栋],P32-ROW(工单[#Headers])))*(工单[房号/位置]=INDEX(工单[房号/位置],P32-ROW(工单[#Headers])))*ROW(工单[楼栋])))) -> 105
A33: =IF($Q33=0,"",INDEX(工单[楼栋],$Q33-ROW(工单[#Headers]))&"") -> 5栋 | B33: =IF($Q33=0,"",INDEX(工单[房号/位置],$Q33-ROW(工单[#Headers]))&"") -> 503 | C33: =IF($Q33=0,"",COUNTIFS(工单[楼栋],A33,工单[房号/位置],B33)) -> 2 | D33: =IF($Q33=0,"",INDEX(工单[报修日期],$Q33-ROW(工单[#Headers]))) -> 45779 | E33: =IF($Q33=0,"",INDEX(工单[报修问题描述],$Q33-ROW(工单[#Headers]))&"") -> 厨房、卫生间门槛石松动 | H33: =IF($Q33=0,"",INDEX(工单[维修类别],$Q33-ROW(工单[#Headers]))&"") -> 墙地饰面 | I33: =IF($Q33=0,"",INDEX(工单[跟进人1],$Q33-ROW(工单[#Headers]))&"") -> 李师傅 | J33: =IF($Q33=0,"",INDEX(工单[完成情况],$Q33-ROW(工单[#Headers]))&"") -> 已完成 | K33: =IF($Q33=0,"",INDEX(工单[维修评价],$Q33-ROW(工单[#Headers]))&"") -> 非常满意 | L33: =IF($Q33=0,"",INDEX(工单[维修备注],$Q33-ROW(工单[#Headers]))&"") | P33: =IFERROR(SUMPRODUCT(LARGE((工单[该户第几次]=2)*ROW(工单[该户第几次]),4)),0) -> 55 | Q33: =IF(P33=0,0,SUMPRODUCT(MAX((工单[楼栋]=INDEX(工单[楼栋],P33-ROW(工单[#Headers])))*(工单[房号/位置]=INDEX(工单[房号/位置],P33-ROW(工单[#Headers])))*ROW(工单[楼栋])))) -> 55
A34: =IF($Q34=0,"",INDEX(工单[楼栋],$Q34-ROW(工单[#Headers]))&"") -> 公共区域 | B34: =IF($Q34=0,"",INDEX(工单[房号/位置],$Q34-ROW(工单[#Headers]))&"") -> 东大门 | C34: =IF($Q34=0,"",COUNTIFS(工单[楼栋],A34,工单[房号/位置],B34)) -> 2 | D34: =IF($Q34=0,"",INDEX(工单[报修日期],$Q34-ROW(工单[#Headers]))) -> 45778 | E34: =IF($Q34=0,"",INDEX(工单[报修问题描述],$Q34-ROW(工单[#Headers]))&"") -> 门岗天花受潮破损修缮 | H34: =IF($Q34=0,"",INDEX(工单[维修类别],$Q34-ROW(工单[#Headers]))&"") -> 墙地饰面 | I34: =IF($Q34=0,"",INDEX(工单[跟进人1],$Q34-ROW(工单[#Headers]))&"") -> 刘师傅 | J34: =IF($Q34=0,"",INDEX(工单[完成情况],$Q34-ROW(工单[#Headers]))&"") -> 跟进中 | K34: =IF($Q34=0,"",INDEX(工单[维修评价],$Q34-ROW(工单[#Headers]))&"") | L34: =IF($Q34=0,"",INDEX(工单[维修备注],$Q34-ROW(工单[#Headers]))&"") -> 已补洞批腻子，待干燥后打磨刷乳胶漆 | P34: =IFERROR(SUMPRODUCT(LARGE((工单[该户第几次]=2)*ROW(工单[该户第几次]),5)),0) -> 39 | Q34: =IF(P34=0,0,SUMPRODUCT(MAX((工单[楼栋]=INDEX(工单[楼栋],P34-ROW(工单[#Headers])))*(工单[房号/位置]=INDEX(工单[房号/位置],P34-ROW(工单[#Headers])))*ROW(工单[楼栋])))) -> 39
A35: =IF($Q35=0,"",INDEX(工单[楼栋],$Q35-ROW(工单[#Headers]))&"") | B35: =IF($Q35=0,"",INDEX(工单[房号/位置],$Q35-ROW(工单[#Headers]))&"") | C35: =IF($Q35=0,"",COUNTIFS(工单[楼栋],A35,工单[房号/位置],B35)) | D35: =IF($Q35=0,"",INDEX(工单[报修日期],$Q35-ROW(工单[#Headers]))) | E35: =IF($Q35=0,"",INDEX(工单[报修问题描述],$Q35-ROW(工单[#Headers]))&"") | H35: =IF($Q35=0,"",INDEX(工单[维修类别],$Q35-ROW(工单[#Headers]))&"") | I35: =IF($Q35=0,"",INDEX(工单[跟进人1],$Q35-ROW(工单[#Headers]))&"") | J35: =IF($Q35=0,"",INDEX(工单[完成情况],$Q35-ROW(工单[#Headers]))&"") | K35: =IF($Q35=0,"",INDEX(工单[维修评价],$Q35-ROW(工单[#Headers]))&"") | L35: =IF($Q35=0,"",INDEX(工单[维修备注],$Q35-ROW(工单[#Headers]))&"") | P35: =IFERROR(SUMPRODUCT(LARGE((工单[该户第几次]=2)*ROW(工单[该户第几次]),6)),0) -> 0 | Q35: =IF(P35=0,0,SUMPRODUCT(MAX((工单[楼栋]=INDEX(工单[楼栋],P35-ROW(工单[#Headers])))*(工单[房号/位置]=INDEX(工单[房号/位置],P35-ROW(工单[#Headers])))*ROW(工单[楼栋])))) -> 0
